2023-09-13 22:46:48,462 - ERROR - No API key provided. You can set your API key in code using 'openai.api_key = <API-KEY>', or you can set the environment variable OPENAI_API_KEY=<API-KEY>). If your API key is stored in a file, you can point the openai module at it with 'openai.api_key_path = <PATH>'. You can generate API keys in the OpenAI web interface. See https://platform.openai.com/account/api-keys for details.
2023-09-13 22:47:25,193 - ERROR - No API key provided. You can set your API key in code using 'openai.api_key = <API-KEY>', or you can set the environment variable OPENAI_API_KEY=<API-KEY>). If your API key is stored in a file, you can point the openai module at it with 'openai.api_key_path = <PATH>'. You can generate API keys in the OpenAI web interface. See https://platform.openai.com/account/api-keys for details.
2023-09-13 22:50:40,342 - ERROR - Incorrect API key provided: sk-A3ieb***************************************deYp. You can find your API key at https://platform.openai.com/account/api-keys.
2023-09-13 22:51:04,923 - ERROR - Incorrect API key provided: sk-A3ieb***************************************deYp. You can find your API key at https://platform.openai.com/account/api-keys.
2023-09-13 22:51:11,988 - ERROR - Incorrect API key provided: sk-A3ieb***************************************deYp. You can find your API key at https://platform.openai.com/account/api-keys.
2023-09-13 22:52:27,786 - ERROR - Incorrect API key provided: sk-A3ieb***************************************deYp. You can find your API key at https://platform.openai.com/account/api-keys.
2023-09-13 23:00:38,273 - ERROR - expected str, bytes or os.PathLike object, not UploadFile
2023-09-13 23:00:53,252 - ERROR - expected str, bytes or os.PathLike object, not UploadFile
2023-09-13 23:01:57,360 - ERROR - expected str, bytes or os.PathLike object, not UploadFile
2023-09-13 23:03:54,002 - ERROR - expected str, bytes or os.PathLike object, not UploadFile
2023-09-13 23:10:18,425 - ERROR - expected str, bytes or os.PathLike object, not UploadFile
2023-09-13 23:10:20,280 - ERROR - expected str, bytes or os.PathLike object, not UploadFile
2023-09-13 23:10:21,164 - ERROR - expected str, bytes or os.PathLike object, not UploadFile
2023-09-13 23:10:21,900 - ERROR - expected str, bytes or os.PathLike object, not UploadFile
2023-09-13 23:10:22,218 - ERROR - expected str, bytes or os.PathLike object, not UploadFile
2023-09-13 23:10:22,563 - ERROR - expected str, bytes or os.PathLike object, not UploadFile
2023-09-13 23:10:22,862 - ERROR - expected str, bytes or os.PathLike object, not UploadFile
2023-09-13 23:11:55,245 - ERROR - expected str, bytes or os.PathLike object, not UploadFile
2023-09-13 23:19:04,768 - ERROR - Must pass 2-d input. shape=(1, 49, 12)
2023-09-13 23:19:32,491 - ERROR - Must pass 2-d input. shape=(1, 49, 12)
2023-09-13 23:20:04,677 - ERROR - Must pass 2-d input. shape=(1, 49, 12)
2023-09-13 23:20:16,855 - ERROR - Must pass 2-d input. shape=(1, 49, 12)
2023-09-13 23:20:53,108 - ERROR - Must pass 2-d input. shape=(1, 49, 12)
2023-09-13 23:21:16,185 - ERROR - Must pass 2-d input. shape=(1, 49, 12)
2023-09-13 23:22:45,047 - ERROR - Must pass 2-d input. shape=(1, 49, 12)
2023-09-13 23:23:06,744 - ERROR - Must pass 2-d input. shape=(1, 49, 12)
2023-09-13 23:23:29,613 - ERROR - Must pass 2-d input. shape=(1, 49, 12)
2023-09-13 23:23:55,968 - ERROR - Must pass 2-d input. shape=(1, 49, 12)
2023-09-14 09:50:48,746 - ERROR - Must pass 2-d input. shape=(1, 480, 12)
2023-09-14 09:51:52,490 - ERROR - Must pass 2-d input. shape=(1, 480, 12)
2023-09-14 09:52:20,655 - ERROR - Must pass 2-d input. shape=(1, 480, 12)
2023-09-14 09:53:17,533 - ERROR - Must pass 2-d input. shape=(1, 480, 12)
2023-09-14 10:03:40,808 - ERROR - 'tuple' object is not callable
2023-09-14 10:23:25,844 - ERROR - "['LOAN_ID'] not found in axis"
2023-09-14 10:24:09,976 - ERROR - "['LOAN_ID'] not found in axis"
2023-09-14 10:24:39,365 - ERROR - "['LOAN_ID'] not found in axis"
2023-09-14 10:25:05,932 - ERROR - "['LOAN_ID'] not found in axis"
2023-09-14 10:35:13,093 - ERROR - Error tokenizing data. C error: Expected 1 fields in line 3, saw 2

2023-09-14 10:37:22,713 - ERROR - could not convert string to float: ' ago'
2023-09-14 10:37:45,906 - ERROR - could not convert string to float: ' ago'
2023-09-14 10:48:20,914 - ERROR - could not convert string to float: ' maps'
2023-09-14 10:48:45,442 - ERROR - could not convert string to float: ' maps'
2023-09-14 11:02:31,423 - ERROR - 
All the 135 fits failed.
It is very likely that your model is misconfigured.
You can try to debug the error by setting error_score='raise'.

Below are more details about the failures:
--------------------------------------------------------------------------------
108 fits failed with the following error:
Traceback (most recent call last):
  File "C:\Users\Akash\AppData\Local\Programs\Python\Python311\Lib\site-packages\sklearn\model_selection\_validation.py", line 732, in _fit_and_score
    estimator.fit(X_train, y_train, **fit_params)
  File "C:\Users\Akash\AppData\Local\Programs\Python\Python311\Lib\site-packages\sklearn\base.py", line 1151, in wrapper
    return fit_method(estimator, *args, **kwargs)
           ^^^^^^^^^^^^^^^^^^^^^^^^^^^^^^^^^^^^^^
  File "C:\Users\Akash\AppData\Local\Programs\Python\Python311\Lib\site-packages\sklearn\ensemble\_forest.py", line 348, in fit
    X, y = self._validate_data(
           ^^^^^^^^^^^^^^^^^^^^
  File "C:\Users\Akash\AppData\Local\Programs\Python\Python311\Lib\site-packages\sklearn\base.py", line 621, in _validate_data
    X, y = check_X_y(X, y, **check_params)
           ^^^^^^^^^^^^^^^^^^^^^^^^^^^^^^^
  File "C:\Users\Akash\AppData\Local\Programs\Python\Python311\Lib\site-packages\sklearn\utils\validation.py", line 1147, in check_X_y
    X = check_array(
        ^^^^^^^^^^^^
  File "C:\Users\Akash\AppData\Local\Programs\Python\Python311\Lib\site-packages\sklearn\utils\validation.py", line 917, in check_array
    array = _asarray_with_order(array, order=order, dtype=dtype, xp=xp)
            ^^^^^^^^^^^^^^^^^^^^^^^^^^^^^^^^^^^^^^^^^^^^^^^^^^^^^^^^^^^
  File "C:\Users\Akash\AppData\Local\Programs\Python\Python311\Lib\site-packages\sklearn\utils\_array_api.py", line 380, in _asarray_with_order
    array = numpy.asarray(array, order=order, dtype=dtype)
            ^^^^^^^^^^^^^^^^^^^^^^^^^^^^^^^^^^^^^^^^^^^^^^
  File "C:\Users\Akash\AppData\Local\Programs\Python\Python311\Lib\site-packages\pandas\core\generic.py", line 1998, in __array__
    arr = np.asarray(values, dtype=dtype)
          ^^^^^^^^^^^^^^^^^^^^^^^^^^^^^^^
ValueError: could not convert string to float: ' maps'

--------------------------------------------------------------------------------
27 fits failed with the following error:
Traceback (most recent call last):
  File "C:\Users\Akash\AppData\Local\Programs\Python\Python311\Lib\site-packages\sklearn\model_selection\_validation.py", line 732, in _fit_and_score
    estimator.fit(X_train, y_train, **fit_params)
  File "C:\Users\Akash\AppData\Local\Programs\Python\Python311\Lib\site-packages\sklearn\base.py", line 1151, in wrapper
    return fit_method(estimator, *args, **kwargs)
           ^^^^^^^^^^^^^^^^^^^^^^^^^^^^^^^^^^^^^^
  File "C:\Users\Akash\AppData\Local\Programs\Python\Python311\Lib\site-packages\sklearn\ensemble\_forest.py", line 348, in fit
    X, y = self._validate_data(
           ^^^^^^^^^^^^^^^^^^^^
  File "C:\Users\Akash\AppData\Local\Programs\Python\Python311\Lib\site-packages\sklearn\base.py", line 621, in _validate_data
    X, y = check_X_y(X, y, **check_params)
           ^^^^^^^^^^^^^^^^^^^^^^^^^^^^^^^
  File "C:\Users\Akash\AppData\Local\Programs\Python\Python311\Lib\site-packages\sklearn\utils\validation.py", line 1147, in check_X_y
    X = check_array(
        ^^^^^^^^^^^^
  File "C:\Users\Akash\AppData\Local\Programs\Python\Python311\Lib\site-packages\sklearn\utils\validation.py", line 917, in check_array
    array = _asarray_with_order(array, order=order, dtype=dtype, xp=xp)
            ^^^^^^^^^^^^^^^^^^^^^^^^^^^^^^^^^^^^^^^^^^^^^^^^^^^^^^^^^^^
  File "C:\Users\Akash\AppData\Local\Programs\Python\Python311\Lib\site-packages\sklearn\utils\_array_api.py", line 380, in _asarray_with_order
    array = numpy.asarray(array, order=order, dtype=dtype)
            ^^^^^^^^^^^^^^^^^^^^^^^^^^^^^^^^^^^^^^^^^^^^^^
  File "C:\Users\Akash\AppData\Local\Programs\Python\Python311\Lib\site-packages\pandas\core\generic.py", line 1998, in __array__
    arr = np.asarray(values, dtype=dtype)
          ^^^^^^^^^^^^^^^^^^^^^^^^^^^^^^^
ValueError: could not convert string to float: '3 Well'

2023-09-14 11:02:31,810 - ERROR - 
All the 135 fits failed.
It is very likely that your model is misconfigured.
You can try to debug the error by setting error_score='raise'.

Below are more details about the failures:
--------------------------------------------------------------------------------
108 fits failed with the following error:
Traceback (most recent call last):
  File "C:\Users\Akash\AppData\Local\Programs\Python\Python311\Lib\site-packages\sklearn\model_selection\_validation.py", line 732, in _fit_and_score
    estimator.fit(X_train, y_train, **fit_params)
  File "C:\Users\Akash\AppData\Local\Programs\Python\Python311\Lib\site-packages\sklearn\base.py", line 1151, in wrapper
    return fit_method(estimator, *args, **kwargs)
           ^^^^^^^^^^^^^^^^^^^^^^^^^^^^^^^^^^^^^^
  File "C:\Users\Akash\AppData\Local\Programs\Python\Python311\Lib\site-packages\sklearn\ensemble\_forest.py", line 348, in fit
    X, y = self._validate_data(
           ^^^^^^^^^^^^^^^^^^^^
  File "C:\Users\Akash\AppData\Local\Programs\Python\Python311\Lib\site-packages\sklearn\base.py", line 621, in _validate_data
    X, y = check_X_y(X, y, **check_params)
           ^^^^^^^^^^^^^^^^^^^^^^^^^^^^^^^
  File "C:\Users\Akash\AppData\Local\Programs\Python\Python311\Lib\site-packages\sklearn\utils\validation.py", line 1147, in check_X_y
    X = check_array(
        ^^^^^^^^^^^^
  File "C:\Users\Akash\AppData\Local\Programs\Python\Python311\Lib\site-packages\sklearn\utils\validation.py", line 917, in check_array
    array = _asarray_with_order(array, order=order, dtype=dtype, xp=xp)
            ^^^^^^^^^^^^^^^^^^^^^^^^^^^^^^^^^^^^^^^^^^^^^^^^^^^^^^^^^^^
  File "C:\Users\Akash\AppData\Local\Programs\Python\Python311\Lib\site-packages\sklearn\utils\_array_api.py", line 380, in _asarray_with_order
    array = numpy.asarray(array, order=order, dtype=dtype)
            ^^^^^^^^^^^^^^^^^^^^^^^^^^^^^^^^^^^^^^^^^^^^^^
  File "C:\Users\Akash\AppData\Local\Programs\Python\Python311\Lib\site-packages\pandas\core\generic.py", line 1998, in __array__
    arr = np.asarray(values, dtype=dtype)
          ^^^^^^^^^^^^^^^^^^^^^^^^^^^^^^^
ValueError: could not convert string to float: ' maps'

--------------------------------------------------------------------------------
27 fits failed with the following error:
Traceback (most recent call last):
  File "C:\Users\Akash\AppData\Local\Programs\Python\Python311\Lib\site-packages\sklearn\model_selection\_validation.py", line 732, in _fit_and_score
    estimator.fit(X_train, y_train, **fit_params)
  File "C:\Users\Akash\AppData\Local\Programs\Python\Python311\Lib\site-packages\sklearn\base.py", line 1151, in wrapper
    return fit_method(estimator, *args, **kwargs)
           ^^^^^^^^^^^^^^^^^^^^^^^^^^^^^^^^^^^^^^
  File "C:\Users\Akash\AppData\Local\Programs\Python\Python311\Lib\site-packages\sklearn\ensemble\_forest.py", line 348, in fit
    X, y = self._validate_data(
           ^^^^^^^^^^^^^^^^^^^^
  File "C:\Users\Akash\AppData\Local\Programs\Python\Python311\Lib\site-packages\sklearn\base.py", line 621, in _validate_data
    X, y = check_X_y(X, y, **check_params)
           ^^^^^^^^^^^^^^^^^^^^^^^^^^^^^^^
  File "C:\Users\Akash\AppData\Local\Programs\Python\Python311\Lib\site-packages\sklearn\utils\validation.py", line 1147, in check_X_y
    X = check_array(
        ^^^^^^^^^^^^
  File "C:\Users\Akash\AppData\Local\Programs\Python\Python311\Lib\site-packages\sklearn\utils\validation.py", line 917, in check_array
    array = _asarray_with_order(array, order=order, dtype=dtype, xp=xp)
            ^^^^^^^^^^^^^^^^^^^^^^^^^^^^^^^^^^^^^^^^^^^^^^^^^^^^^^^^^^^
  File "C:\Users\Akash\AppData\Local\Programs\Python\Python311\Lib\site-packages\sklearn\utils\_array_api.py", line 380, in _asarray_with_order
    array = numpy.asarray(array, order=order, dtype=dtype)
            ^^^^^^^^^^^^^^^^^^^^^^^^^^^^^^^^^^^^^^^^^^^^^^
  File "C:\Users\Akash\AppData\Local\Programs\Python\Python311\Lib\site-packages\pandas\core\generic.py", line 1998, in __array__
    arr = np.asarray(values, dtype=dtype)
          ^^^^^^^^^^^^^^^^^^^^^^^^^^^^^^^
ValueError: could not convert string to float: '3 Well'

2023-09-14 11:08:29,949 - ERROR - Error tokenizing data. C error: Expected 13 fields in line 16, saw 15

2023-09-14 11:10:09,964 - ERROR - Error tokenizing data. C error: Expected 13 fields in line 38, saw 14

2023-09-14 11:12:13,636 - ERROR - [WinError 2] The system cannot find the file specified: '/api/uploads\\Loan_data_Train.csv'
2023-09-14 11:15:50,678 - ERROR - 
All the 135 fits failed.
It is very likely that your model is misconfigured.
You can try to debug the error by setting error_score='raise'.

Below are more details about the failures:
--------------------------------------------------------------------------------
27 fits failed with the following error:
Traceback (most recent call last):
  File "C:\Users\Akash\AppData\Local\Programs\Python\Python311\Lib\site-packages\sklearn\model_selection\_validation.py", line 732, in _fit_and_score
    estimator.fit(X_train, y_train, **fit_params)
  File "C:\Users\Akash\AppData\Local\Programs\Python\Python311\Lib\site-packages\sklearn\base.py", line 1151, in wrapper
    return fit_method(estimator, *args, **kwargs)
           ^^^^^^^^^^^^^^^^^^^^^^^^^^^^^^^^^^^^^^
  File "C:\Users\Akash\AppData\Local\Programs\Python\Python311\Lib\site-packages\sklearn\ensemble\_forest.py", line 348, in fit
    X, y = self._validate_data(
           ^^^^^^^^^^^^^^^^^^^^
  File "C:\Users\Akash\AppData\Local\Programs\Python\Python311\Lib\site-packages\sklearn\base.py", line 621, in _validate_data
    X, y = check_X_y(X, y, **check_params)
           ^^^^^^^^^^^^^^^^^^^^^^^^^^^^^^^
  File "C:\Users\Akash\AppData\Local\Programs\Python\Python311\Lib\site-packages\sklearn\utils\validation.py", line 1147, in check_X_y
    X = check_array(
        ^^^^^^^^^^^^
  File "C:\Users\Akash\AppData\Local\Programs\Python\Python311\Lib\site-packages\sklearn\utils\validation.py", line 917, in check_array
    array = _asarray_with_order(array, order=order, dtype=dtype, xp=xp)
            ^^^^^^^^^^^^^^^^^^^^^^^^^^^^^^^^^^^^^^^^^^^^^^^^^^^^^^^^^^^
  File "C:\Users\Akash\AppData\Local\Programs\Python\Python311\Lib\site-packages\sklearn\utils\_array_api.py", line 380, in _asarray_with_order
    array = numpy.asarray(array, order=order, dtype=dtype)
            ^^^^^^^^^^^^^^^^^^^^^^^^^^^^^^^^^^^^^^^^^^^^^^
  File "C:\Users\Akash\AppData\Local\Programs\Python\Python311\Lib\site-packages\pandas\core\generic.py", line 1998, in __array__
    arr = np.asarray(values, dtype=dtype)
          ^^^^^^^^^^^^^^^^^^^^^^^^^^^^^^^
ValueError: could not convert string to float: 'feee'

--------------------------------------------------------------------------------
108 fits failed with the following error:
Traceback (most recent call last):
  File "C:\Users\Akash\AppData\Local\Programs\Python\Python311\Lib\site-packages\sklearn\model_selection\_validation.py", line 732, in _fit_and_score
    estimator.fit(X_train, y_train, **fit_params)
  File "C:\Users\Akash\AppData\Local\Programs\Python\Python311\Lib\site-packages\sklearn\base.py", line 1151, in wrapper
    return fit_method(estimator, *args, **kwargs)
           ^^^^^^^^^^^^^^^^^^^^^^^^^^^^^^^^^^^^^^
  File "C:\Users\Akash\AppData\Local\Programs\Python\Python311\Lib\site-packages\sklearn\ensemble\_forest.py", line 348, in fit
    X, y = self._validate_data(
           ^^^^^^^^^^^^^^^^^^^^
  File "C:\Users\Akash\AppData\Local\Programs\Python\Python311\Lib\site-packages\sklearn\base.py", line 621, in _validate_data
    X, y = check_X_y(X, y, **check_params)
           ^^^^^^^^^^^^^^^^^^^^^^^^^^^^^^^
  File "C:\Users\Akash\AppData\Local\Programs\Python\Python311\Lib\site-packages\sklearn\utils\validation.py", line 1147, in check_X_y
    X = check_array(
        ^^^^^^^^^^^^
  File "C:\Users\Akash\AppData\Local\Programs\Python\Python311\Lib\site-packages\sklearn\utils\validation.py", line 917, in check_array
    array = _asarray_with_order(array, order=order, dtype=dtype, xp=xp)
            ^^^^^^^^^^^^^^^^^^^^^^^^^^^^^^^^^^^^^^^^^^^^^^^^^^^^^^^^^^^
  File "C:\Users\Akash\AppData\Local\Programs\Python\Python311\Lib\site-packages\sklearn\utils\_array_api.py", line 380, in _asarray_with_order
    array = numpy.asarray(array, order=order, dtype=dtype)
            ^^^^^^^^^^^^^^^^^^^^^^^^^^^^^^^^^^^^^^^^^^^^^^
  File "C:\Users\Akash\AppData\Local\Programs\Python\Python311\Lib\site-packages\pandas\core\generic.py", line 1998, in __array__
    arr = np.asarray(values, dtype=dtype)
          ^^^^^^^^^^^^^^^^^^^^^^^^^^^^^^^
ValueError: could not convert string to float: 'signs'

2023-09-14 11:16:16,900 - ERROR - 
All the 135 fits failed.
It is very likely that your model is misconfigured.
You can try to debug the error by setting error_score='raise'.

Below are more details about the failures:
--------------------------------------------------------------------------------
27 fits failed with the following error:
Traceback (most recent call last):
  File "C:\Users\Akash\AppData\Local\Programs\Python\Python311\Lib\site-packages\sklearn\model_selection\_validation.py", line 732, in _fit_and_score
    estimator.fit(X_train, y_train, **fit_params)
  File "C:\Users\Akash\AppData\Local\Programs\Python\Python311\Lib\site-packages\sklearn\base.py", line 1151, in wrapper
    return fit_method(estimator, *args, **kwargs)
           ^^^^^^^^^^^^^^^^^^^^^^^^^^^^^^^^^^^^^^
  File "C:\Users\Akash\AppData\Local\Programs\Python\Python311\Lib\site-packages\sklearn\ensemble\_forest.py", line 348, in fit
    X, y = self._validate_data(
           ^^^^^^^^^^^^^^^^^^^^
  File "C:\Users\Akash\AppData\Local\Programs\Python\Python311\Lib\site-packages\sklearn\base.py", line 621, in _validate_data
    X, y = check_X_y(X, y, **check_params)
           ^^^^^^^^^^^^^^^^^^^^^^^^^^^^^^^
  File "C:\Users\Akash\AppData\Local\Programs\Python\Python311\Lib\site-packages\sklearn\utils\validation.py", line 1147, in check_X_y
    X = check_array(
        ^^^^^^^^^^^^
  File "C:\Users\Akash\AppData\Local\Programs\Python\Python311\Lib\site-packages\sklearn\utils\validation.py", line 917, in check_array
    array = _asarray_with_order(array, order=order, dtype=dtype, xp=xp)
            ^^^^^^^^^^^^^^^^^^^^^^^^^^^^^^^^^^^^^^^^^^^^^^^^^^^^^^^^^^^
  File "C:\Users\Akash\AppData\Local\Programs\Python\Python311\Lib\site-packages\sklearn\utils\_array_api.py", line 380, in _asarray_with_order
    array = numpy.asarray(array, order=order, dtype=dtype)
            ^^^^^^^^^^^^^^^^^^^^^^^^^^^^^^^^^^^^^^^^^^^^^^
  File "C:\Users\Akash\AppData\Local\Programs\Python\Python311\Lib\site-packages\pandas\core\generic.py", line 1998, in __array__
    arr = np.asarray(values, dtype=dtype)
          ^^^^^^^^^^^^^^^^^^^^^^^^^^^^^^^
ValueError: could not convert string to float: 'feee'

--------------------------------------------------------------------------------
108 fits failed with the following error:
Traceback (most recent call last):
  File "C:\Users\Akash\AppData\Local\Programs\Python\Python311\Lib\site-packages\sklearn\model_selection\_validation.py", line 732, in _fit_and_score
    estimator.fit(X_train, y_train, **fit_params)
  File "C:\Users\Akash\AppData\Local\Programs\Python\Python311\Lib\site-packages\sklearn\base.py", line 1151, in wrapper
    return fit_method(estimator, *args, **kwargs)
           ^^^^^^^^^^^^^^^^^^^^^^^^^^^^^^^^^^^^^^
  File "C:\Users\Akash\AppData\Local\Programs\Python\Python311\Lib\site-packages\sklearn\ensemble\_forest.py", line 348, in fit
    X, y = self._validate_data(
           ^^^^^^^^^^^^^^^^^^^^
  File "C:\Users\Akash\AppData\Local\Programs\Python\Python311\Lib\site-packages\sklearn\base.py", line 621, in _validate_data
    X, y = check_X_y(X, y, **check_params)
           ^^^^^^^^^^^^^^^^^^^^^^^^^^^^^^^
  File "C:\Users\Akash\AppData\Local\Programs\Python\Python311\Lib\site-packages\sklearn\utils\validation.py", line 1147, in check_X_y
    X = check_array(
        ^^^^^^^^^^^^
  File "C:\Users\Akash\AppData\Local\Programs\Python\Python311\Lib\site-packages\sklearn\utils\validation.py", line 917, in check_array
    array = _asarray_with_order(array, order=order, dtype=dtype, xp=xp)
            ^^^^^^^^^^^^^^^^^^^^^^^^^^^^^^^^^^^^^^^^^^^^^^^^^^^^^^^^^^^
  File "C:\Users\Akash\AppData\Local\Programs\Python\Python311\Lib\site-packages\sklearn\utils\_array_api.py", line 380, in _asarray_with_order
    array = numpy.asarray(array, order=order, dtype=dtype)
            ^^^^^^^^^^^^^^^^^^^^^^^^^^^^^^^^^^^^^^^^^^^^^^
  File "C:\Users\Akash\AppData\Local\Programs\Python\Python311\Lib\site-packages\pandas\core\generic.py", line 1998, in __array__
    arr = np.asarray(values, dtype=dtype)
          ^^^^^^^^^^^^^^^^^^^^^^^^^^^^^^^
ValueError: could not convert string to float: 'signs'

2023-09-14 11:18:09,149 - ERROR - Error tokenizing data. C error: Expected 13 fields in line 69, saw 15

2023-09-14 11:31:11,698 - ERROR - concat() takes 1 positional argument but 2 were given
2023-09-14 11:37:19,758 - ERROR - No columns to parse from file
2023-09-14 11:38:15,057 - ERROR - Error tokenizing data. C error: Expected 13 fields in line 52, saw 14

2023-09-14 11:42:36,091 - ERROR - Error tokenizing data. C error: EOF inside string starting at row 74
2023-09-14 11:43:05,606 - ERROR - 'Loan_Status'
2023-09-14 11:43:47,974 - ERROR - 'DataFrame' object has no attribute 'synthetic_data'
2023-09-14 11:44:50,567 - ERROR - 'Loan_status'
2023-09-14 11:47:10,797 - ERROR - 'Loan_status'
2023-09-14 11:49:02,192 - ERROR - 'Loan_status'
2023-09-14 11:51:01,473 - ERROR - 'Loan_status'
2023-09-14 11:52:44,070 - ERROR - Must pass 2-d input. shape=(1, 480, 12)
2023-09-14 11:53:43,395 - ERROR - Must pass 2-d input. shape=(1, 480, 12)
2023-09-14 11:53:48,203 - ERROR - Must pass 2-d input. shape=(1, 480, 12)
2023-09-14 11:54:38,737 - ERROR - Must pass 2-d input. shape=(1, 480, 12)
2023-09-14 11:54:42,634 - ERROR - Must pass 2-d input. shape=(1, 480, 12)
2023-09-14 11:54:43,689 - ERROR - Must pass 2-d input. shape=(1, 480, 12)
2023-09-14 11:54:52,458 - ERROR - Must pass 2-d input. shape=(1, 480, 12)
2023-09-14 11:54:53,233 - ERROR - Must pass 2-d input. shape=(1, 480, 12)
2023-09-14 11:54:53,417 - ERROR - Must pass 2-d input. shape=(1, 480, 12)
2023-09-14 11:54:53,681 - ERROR - Must pass 2-d input. shape=(1, 480, 12)
2023-09-14 11:57:11,873 - ERROR - Must pass 2-d input. shape=(1, 480, 12)
2023-09-14 11:57:37,164 - ERROR - Must pass 2-d input. shape=(1, 480, 12)
2023-09-14 11:57:56,599 - ERROR - Must pass 2-d input. shape=(1, 480, 12)
2023-09-14 11:57:57,828 - ERROR - Must pass 2-d input. shape=(1, 480, 12)
2023-09-14 11:57:59,847 - ERROR - Must pass 2-d input. shape=(1, 480, 12)
2023-09-14 11:58:00,676 - ERROR - Must pass 2-d input. shape=(1, 480, 12)
2023-09-14 11:58:01,365 - ERROR - Must pass 2-d input. shape=(1, 480, 12)
2023-09-14 11:58:03,187 - ERROR - Must pass 2-d input. shape=(1, 480, 12)
2023-09-14 11:58:03,789 - ERROR - Must pass 2-d input. shape=(1, 480, 12)
2023-09-14 11:58:03,987 - ERROR - Must pass 2-d input. shape=(1, 480, 12)
2023-09-14 11:58:04,197 - ERROR - Must pass 2-d input. shape=(1, 480, 12)
2023-09-14 11:58:04,395 - ERROR - Must pass 2-d input. shape=(1, 480, 12)
2023-09-14 11:58:35,143 - ERROR - Must pass 2-d input. shape=(1, 480, 12)
2023-09-14 11:58:48,857 - ERROR - Must pass 2-d input. shape=(1, 480, 12)
2023-09-14 12:18:14,574 - ERROR - Error tokenizing data. C error: Expected 13 fields in line 10, saw 14

2023-09-14 12:18:43,805 - ERROR - 'Loan_Status'
2023-09-14 12:19:13,297 - ERROR - Error tokenizing data. C error: EOF inside string starting at row 0
2023-09-14 12:20:03,643 - ERROR - Error tokenizing data. C error: Expected 1 fields in line 9, saw 3

2023-09-14 12:22:13,075 - ERROR - 'Loan_Status'
2023-09-14 12:22:52,326 - ERROR - 'Loan_Status'
2023-09-14 12:24:09,796 - ERROR - 'Loan_Status'
2023-09-14 12:24:23,642 - ERROR - Error tokenizing data. C error: Expected 1 fields in line 5, saw 4

2023-09-14 12:27:22,794 - ERROR - Error tokenizing data. C error: EOF inside string starting at row 1
2023-09-14 12:28:20,675 - ERROR - Error tokenizing data. C error: Expected 178 fields in line 3, saw 230

2023-09-14 12:28:25,695 - ERROR - 'Loan_Status'
2023-09-14 12:29:01,598 - ERROR - Error tokenizing data. C error: Expected 1 fields in line 49, saw 2

2023-09-14 12:30:18,365 - ERROR - 'Loan_Status'
2023-09-14 12:30:58,890 - ERROR - Error tokenizing data. C error: Expected 1 fields in line 5, saw 13

2023-09-14 12:34:10,094 - ERROR - This model's maximum context length is 2049 tokens, however you requested 3138 tokens (138 in your prompt; 3000 for the completion). Please reduce your prompt; or completion length.
2023-09-14 12:57:39,094 - ERROR - 
All the 135 fits failed.
It is very likely that your model is misconfigured.
You can try to debug the error by setting error_score='raise'.

Below are more details about the failures:
--------------------------------------------------------------------------------
108 fits failed with the following error:
Traceback (most recent call last):
  File "C:\Users\Akash\AppData\Local\Programs\Python\Python311\Lib\site-packages\sklearn\model_selection\_validation.py", line 732, in _fit_and_score
    estimator.fit(X_train, y_train, **fit_params)
  File "C:\Users\Akash\AppData\Local\Programs\Python\Python311\Lib\site-packages\sklearn\base.py", line 1151, in wrapper
    return fit_method(estimator, *args, **kwargs)
           ^^^^^^^^^^^^^^^^^^^^^^^^^^^^^^^^^^^^^^
  File "C:\Users\Akash\AppData\Local\Programs\Python\Python311\Lib\site-packages\sklearn\ensemble\_forest.py", line 348, in fit
    X, y = self._validate_data(
           ^^^^^^^^^^^^^^^^^^^^
  File "C:\Users\Akash\AppData\Local\Programs\Python\Python311\Lib\site-packages\sklearn\base.py", line 621, in _validate_data
    X, y = check_X_y(X, y, **check_params)
           ^^^^^^^^^^^^^^^^^^^^^^^^^^^^^^^
  File "C:\Users\Akash\AppData\Local\Programs\Python\Python311\Lib\site-packages\sklearn\utils\validation.py", line 1147, in check_X_y
    X = check_array(
        ^^^^^^^^^^^^
  File "C:\Users\Akash\AppData\Local\Programs\Python\Python311\Lib\site-packages\sklearn\utils\validation.py", line 917, in check_array
    array = _asarray_with_order(array, order=order, dtype=dtype, xp=xp)
            ^^^^^^^^^^^^^^^^^^^^^^^^^^^^^^^^^^^^^^^^^^^^^^^^^^^^^^^^^^^
  File "C:\Users\Akash\AppData\Local\Programs\Python\Python311\Lib\site-packages\sklearn\utils\_array_api.py", line 380, in _asarray_with_order
    array = numpy.asarray(array, order=order, dtype=dtype)
            ^^^^^^^^^^^^^^^^^^^^^^^^^^^^^^^^^^^^^^^^^^^^^^
  File "C:\Users\Akash\AppData\Local\Programs\Python\Python311\Lib\site-packages\pandas\core\generic.py", line 1998, in __array__
    arr = np.asarray(values, dtype=dtype)
          ^^^^^^^^^^^^^^^^^^^^^^^^^^^^^^^
ValueError: could not convert string to float: ' Simulation'

--------------------------------------------------------------------------------
27 fits failed with the following error:
Traceback (most recent call last):
  File "C:\Users\Akash\AppData\Local\Programs\Python\Python311\Lib\site-packages\sklearn\model_selection\_validation.py", line 732, in _fit_and_score
    estimator.fit(X_train, y_train, **fit_params)
  File "C:\Users\Akash\AppData\Local\Programs\Python\Python311\Lib\site-packages\sklearn\base.py", line 1151, in wrapper
    return fit_method(estimator, *args, **kwargs)
           ^^^^^^^^^^^^^^^^^^^^^^^^^^^^^^^^^^^^^^
  File "C:\Users\Akash\AppData\Local\Programs\Python\Python311\Lib\site-packages\sklearn\ensemble\_forest.py", line 348, in fit
    X, y = self._validate_data(
           ^^^^^^^^^^^^^^^^^^^^
  File "C:\Users\Akash\AppData\Local\Programs\Python\Python311\Lib\site-packages\sklearn\base.py", line 621, in _validate_data
    X, y = check_X_y(X, y, **check_params)
           ^^^^^^^^^^^^^^^^^^^^^^^^^^^^^^^
  File "C:\Users\Akash\AppData\Local\Programs\Python\Python311\Lib\site-packages\sklearn\utils\validation.py", line 1147, in check_X_y
    X = check_array(
        ^^^^^^^^^^^^
  File "C:\Users\Akash\AppData\Local\Programs\Python\Python311\Lib\site-packages\sklearn\utils\validation.py", line 917, in check_array
    array = _asarray_with_order(array, order=order, dtype=dtype, xp=xp)
            ^^^^^^^^^^^^^^^^^^^^^^^^^^^^^^^^^^^^^^^^^^^^^^^^^^^^^^^^^^^
  File "C:\Users\Akash\AppData\Local\Programs\Python\Python311\Lib\site-packages\sklearn\utils\_array_api.py", line 380, in _asarray_with_order
    array = numpy.asarray(array, order=order, dtype=dtype)
            ^^^^^^^^^^^^^^^^^^^^^^^^^^^^^^^^^^^^^^^^^^^^^^
  File "C:\Users\Akash\AppData\Local\Programs\Python\Python311\Lib\site-packages\pandas\core\generic.py", line 1998, in __array__
    arr = np.asarray(values, dtype=dtype)
          ^^^^^^^^^^^^^^^^^^^^^^^^^^^^^^^
ValueError: could not convert string to float: ' Useful'

2023-09-14 12:57:59,155 - ERROR - 
All the 135 fits failed.
It is very likely that your model is misconfigured.
You can try to debug the error by setting error_score='raise'.

Below are more details about the failures:
--------------------------------------------------------------------------------
108 fits failed with the following error:
Traceback (most recent call last):
  File "C:\Users\Akash\AppData\Local\Programs\Python\Python311\Lib\site-packages\sklearn\model_selection\_validation.py", line 732, in _fit_and_score
    estimator.fit(X_train, y_train, **fit_params)
  File "C:\Users\Akash\AppData\Local\Programs\Python\Python311\Lib\site-packages\sklearn\base.py", line 1151, in wrapper
    return fit_method(estimator, *args, **kwargs)
           ^^^^^^^^^^^^^^^^^^^^^^^^^^^^^^^^^^^^^^
  File "C:\Users\Akash\AppData\Local\Programs\Python\Python311\Lib\site-packages\sklearn\ensemble\_forest.py", line 348, in fit
    X, y = self._validate_data(
           ^^^^^^^^^^^^^^^^^^^^
  File "C:\Users\Akash\AppData\Local\Programs\Python\Python311\Lib\site-packages\sklearn\base.py", line 621, in _validate_data
    X, y = check_X_y(X, y, **check_params)
           ^^^^^^^^^^^^^^^^^^^^^^^^^^^^^^^
  File "C:\Users\Akash\AppData\Local\Programs\Python\Python311\Lib\site-packages\sklearn\utils\validation.py", line 1147, in check_X_y
    X = check_array(
        ^^^^^^^^^^^^
  File "C:\Users\Akash\AppData\Local\Programs\Python\Python311\Lib\site-packages\sklearn\utils\validation.py", line 917, in check_array
    array = _asarray_with_order(array, order=order, dtype=dtype, xp=xp)
            ^^^^^^^^^^^^^^^^^^^^^^^^^^^^^^^^^^^^^^^^^^^^^^^^^^^^^^^^^^^
  File "C:\Users\Akash\AppData\Local\Programs\Python\Python311\Lib\site-packages\sklearn\utils\_array_api.py", line 380, in _asarray_with_order
    array = numpy.asarray(array, order=order, dtype=dtype)
            ^^^^^^^^^^^^^^^^^^^^^^^^^^^^^^^^^^^^^^^^^^^^^^
  File "C:\Users\Akash\AppData\Local\Programs\Python\Python311\Lib\site-packages\pandas\core\generic.py", line 1998, in __array__
    arr = np.asarray(values, dtype=dtype)
          ^^^^^^^^^^^^^^^^^^^^^^^^^^^^^^^
ValueError: could not convert string to float: ' Simulation'

--------------------------------------------------------------------------------
27 fits failed with the following error:
Traceback (most recent call last):
  File "C:\Users\Akash\AppData\Local\Programs\Python\Python311\Lib\site-packages\sklearn\model_selection\_validation.py", line 732, in _fit_and_score
    estimator.fit(X_train, y_train, **fit_params)
  File "C:\Users\Akash\AppData\Local\Programs\Python\Python311\Lib\site-packages\sklearn\base.py", line 1151, in wrapper
    return fit_method(estimator, *args, **kwargs)
           ^^^^^^^^^^^^^^^^^^^^^^^^^^^^^^^^^^^^^^
  File "C:\Users\Akash\AppData\Local\Programs\Python\Python311\Lib\site-packages\sklearn\ensemble\_forest.py", line 348, in fit
    X, y = self._validate_data(
           ^^^^^^^^^^^^^^^^^^^^
  File "C:\Users\Akash\AppData\Local\Programs\Python\Python311\Lib\site-packages\sklearn\base.py", line 621, in _validate_data
    X, y = check_X_y(X, y, **check_params)
           ^^^^^^^^^^^^^^^^^^^^^^^^^^^^^^^
  File "C:\Users\Akash\AppData\Local\Programs\Python\Python311\Lib\site-packages\sklearn\utils\validation.py", line 1147, in check_X_y
    X = check_array(
        ^^^^^^^^^^^^
  File "C:\Users\Akash\AppData\Local\Programs\Python\Python311\Lib\site-packages\sklearn\utils\validation.py", line 917, in check_array
    array = _asarray_with_order(array, order=order, dtype=dtype, xp=xp)
            ^^^^^^^^^^^^^^^^^^^^^^^^^^^^^^^^^^^^^^^^^^^^^^^^^^^^^^^^^^^
  File "C:\Users\Akash\AppData\Local\Programs\Python\Python311\Lib\site-packages\sklearn\utils\_array_api.py", line 380, in _asarray_with_order
    array = numpy.asarray(array, order=order, dtype=dtype)
            ^^^^^^^^^^^^^^^^^^^^^^^^^^^^^^^^^^^^^^^^^^^^^^
  File "C:\Users\Akash\AppData\Local\Programs\Python\Python311\Lib\site-packages\pandas\core\generic.py", line 1998, in __array__
    arr = np.asarray(values, dtype=dtype)
          ^^^^^^^^^^^^^^^^^^^^^^^^^^^^^^^
ValueError: could not convert string to float: ' Useful'

2023-09-14 12:58:46,915 - ERROR - 
All the 135 fits failed.
It is very likely that your model is misconfigured.
You can try to debug the error by setting error_score='raise'.

Below are more details about the failures:
--------------------------------------------------------------------------------
108 fits failed with the following error:
Traceback (most recent call last):
  File "C:\Users\Akash\AppData\Local\Programs\Python\Python311\Lib\site-packages\sklearn\model_selection\_validation.py", line 732, in _fit_and_score
    estimator.fit(X_train, y_train, **fit_params)
  File "C:\Users\Akash\AppData\Local\Programs\Python\Python311\Lib\site-packages\sklearn\base.py", line 1151, in wrapper
    return fit_method(estimator, *args, **kwargs)
           ^^^^^^^^^^^^^^^^^^^^^^^^^^^^^^^^^^^^^^
  File "C:\Users\Akash\AppData\Local\Programs\Python\Python311\Lib\site-packages\sklearn\ensemble\_forest.py", line 348, in fit
    X, y = self._validate_data(
           ^^^^^^^^^^^^^^^^^^^^
  File "C:\Users\Akash\AppData\Local\Programs\Python\Python311\Lib\site-packages\sklearn\base.py", line 621, in _validate_data
    X, y = check_X_y(X, y, **check_params)
           ^^^^^^^^^^^^^^^^^^^^^^^^^^^^^^^
  File "C:\Users\Akash\AppData\Local\Programs\Python\Python311\Lib\site-packages\sklearn\utils\validation.py", line 1147, in check_X_y
    X = check_array(
        ^^^^^^^^^^^^
  File "C:\Users\Akash\AppData\Local\Programs\Python\Python311\Lib\site-packages\sklearn\utils\validation.py", line 917, in check_array
    array = _asarray_with_order(array, order=order, dtype=dtype, xp=xp)
            ^^^^^^^^^^^^^^^^^^^^^^^^^^^^^^^^^^^^^^^^^^^^^^^^^^^^^^^^^^^
  File "C:\Users\Akash\AppData\Local\Programs\Python\Python311\Lib\site-packages\sklearn\utils\_array_api.py", line 380, in _asarray_with_order
    array = numpy.asarray(array, order=order, dtype=dtype)
            ^^^^^^^^^^^^^^^^^^^^^^^^^^^^^^^^^^^^^^^^^^^^^^
  File "C:\Users\Akash\AppData\Local\Programs\Python\Python311\Lib\site-packages\pandas\core\generic.py", line 1998, in __array__
    arr = np.asarray(values, dtype=dtype)
          ^^^^^^^^^^^^^^^^^^^^^^^^^^^^^^^
ValueError: could not convert string to float: ' Simulation'

--------------------------------------------------------------------------------
27 fits failed with the following error:
Traceback (most recent call last):
  File "C:\Users\Akash\AppData\Local\Programs\Python\Python311\Lib\site-packages\sklearn\model_selection\_validation.py", line 732, in _fit_and_score
    estimator.fit(X_train, y_train, **fit_params)
  File "C:\Users\Akash\AppData\Local\Programs\Python\Python311\Lib\site-packages\sklearn\base.py", line 1151, in wrapper
    return fit_method(estimator, *args, **kwargs)
           ^^^^^^^^^^^^^^^^^^^^^^^^^^^^^^^^^^^^^^
  File "C:\Users\Akash\AppData\Local\Programs\Python\Python311\Lib\site-packages\sklearn\ensemble\_forest.py", line 348, in fit
    X, y = self._validate_data(
           ^^^^^^^^^^^^^^^^^^^^
  File "C:\Users\Akash\AppData\Local\Programs\Python\Python311\Lib\site-packages\sklearn\base.py", line 621, in _validate_data
    X, y = check_X_y(X, y, **check_params)
           ^^^^^^^^^^^^^^^^^^^^^^^^^^^^^^^
  File "C:\Users\Akash\AppData\Local\Programs\Python\Python311\Lib\site-packages\sklearn\utils\validation.py", line 1147, in check_X_y
    X = check_array(
        ^^^^^^^^^^^^
  File "C:\Users\Akash\AppData\Local\Programs\Python\Python311\Lib\site-packages\sklearn\utils\validation.py", line 917, in check_array
    array = _asarray_with_order(array, order=order, dtype=dtype, xp=xp)
            ^^^^^^^^^^^^^^^^^^^^^^^^^^^^^^^^^^^^^^^^^^^^^^^^^^^^^^^^^^^
  File "C:\Users\Akash\AppData\Local\Programs\Python\Python311\Lib\site-packages\sklearn\utils\_array_api.py", line 380, in _asarray_with_order
    array = numpy.asarray(array, order=order, dtype=dtype)
            ^^^^^^^^^^^^^^^^^^^^^^^^^^^^^^^^^^^^^^^^^^^^^^
  File "C:\Users\Akash\AppData\Local\Programs\Python\Python311\Lib\site-packages\pandas\core\generic.py", line 1998, in __array__
    arr = np.asarray(values, dtype=dtype)
          ^^^^^^^^^^^^^^^^^^^^^^^^^^^^^^^
ValueError: could not convert string to float: ' Useful'

2023-09-14 12:59:36,482 - ERROR - 
All the 135 fits failed.
It is very likely that your model is misconfigured.
You can try to debug the error by setting error_score='raise'.

Below are more details about the failures:
--------------------------------------------------------------------------------
108 fits failed with the following error:
Traceback (most recent call last):
  File "C:\Users\Akash\AppData\Local\Programs\Python\Python311\Lib\site-packages\sklearn\model_selection\_validation.py", line 732, in _fit_and_score
    estimator.fit(X_train, y_train, **fit_params)
  File "C:\Users\Akash\AppData\Local\Programs\Python\Python311\Lib\site-packages\sklearn\base.py", line 1151, in wrapper
    return fit_method(estimator, *args, **kwargs)
           ^^^^^^^^^^^^^^^^^^^^^^^^^^^^^^^^^^^^^^
  File "C:\Users\Akash\AppData\Local\Programs\Python\Python311\Lib\site-packages\sklearn\ensemble\_forest.py", line 348, in fit
    X, y = self._validate_data(
           ^^^^^^^^^^^^^^^^^^^^
  File "C:\Users\Akash\AppData\Local\Programs\Python\Python311\Lib\site-packages\sklearn\base.py", line 621, in _validate_data
    X, y = check_X_y(X, y, **check_params)
           ^^^^^^^^^^^^^^^^^^^^^^^^^^^^^^^
  File "C:\Users\Akash\AppData\Local\Programs\Python\Python311\Lib\site-packages\sklearn\utils\validation.py", line 1147, in check_X_y
    X = check_array(
        ^^^^^^^^^^^^
  File "C:\Users\Akash\AppData\Local\Programs\Python\Python311\Lib\site-packages\sklearn\utils\validation.py", line 917, in check_array
    array = _asarray_with_order(array, order=order, dtype=dtype, xp=xp)
            ^^^^^^^^^^^^^^^^^^^^^^^^^^^^^^^^^^^^^^^^^^^^^^^^^^^^^^^^^^^
  File "C:\Users\Akash\AppData\Local\Programs\Python\Python311\Lib\site-packages\sklearn\utils\_array_api.py", line 380, in _asarray_with_order
    array = numpy.asarray(array, order=order, dtype=dtype)
            ^^^^^^^^^^^^^^^^^^^^^^^^^^^^^^^^^^^^^^^^^^^^^^
  File "C:\Users\Akash\AppData\Local\Programs\Python\Python311\Lib\site-packages\pandas\core\generic.py", line 1998, in __array__
    arr = np.asarray(values, dtype=dtype)
          ^^^^^^^^^^^^^^^^^^^^^^^^^^^^^^^
ValueError: could not convert string to float: ' Simulation'

--------------------------------------------------------------------------------
27 fits failed with the following error:
Traceback (most recent call last):
  File "C:\Users\Akash\AppData\Local\Programs\Python\Python311\Lib\site-packages\sklearn\model_selection\_validation.py", line 732, in _fit_and_score
    estimator.fit(X_train, y_train, **fit_params)
  File "C:\Users\Akash\AppData\Local\Programs\Python\Python311\Lib\site-packages\sklearn\base.py", line 1151, in wrapper
    return fit_method(estimator, *args, **kwargs)
           ^^^^^^^^^^^^^^^^^^^^^^^^^^^^^^^^^^^^^^
  File "C:\Users\Akash\AppData\Local\Programs\Python\Python311\Lib\site-packages\sklearn\ensemble\_forest.py", line 348, in fit
    X, y = self._validate_data(
           ^^^^^^^^^^^^^^^^^^^^
  File "C:\Users\Akash\AppData\Local\Programs\Python\Python311\Lib\site-packages\sklearn\base.py", line 621, in _validate_data
    X, y = check_X_y(X, y, **check_params)
           ^^^^^^^^^^^^^^^^^^^^^^^^^^^^^^^
  File "C:\Users\Akash\AppData\Local\Programs\Python\Python311\Lib\site-packages\sklearn\utils\validation.py", line 1147, in check_X_y
    X = check_array(
        ^^^^^^^^^^^^
  File "C:\Users\Akash\AppData\Local\Programs\Python\Python311\Lib\site-packages\sklearn\utils\validation.py", line 917, in check_array
    array = _asarray_with_order(array, order=order, dtype=dtype, xp=xp)
            ^^^^^^^^^^^^^^^^^^^^^^^^^^^^^^^^^^^^^^^^^^^^^^^^^^^^^^^^^^^
  File "C:\Users\Akash\AppData\Local\Programs\Python\Python311\Lib\site-packages\sklearn\utils\_array_api.py", line 380, in _asarray_with_order
    array = numpy.asarray(array, order=order, dtype=dtype)
            ^^^^^^^^^^^^^^^^^^^^^^^^^^^^^^^^^^^^^^^^^^^^^^
  File "C:\Users\Akash\AppData\Local\Programs\Python\Python311\Lib\site-packages\pandas\core\generic.py", line 1998, in __array__
    arr = np.asarray(values, dtype=dtype)
          ^^^^^^^^^^^^^^^^^^^^^^^^^^^^^^^
ValueError: could not convert string to float: ' Useful'

2023-09-14 12:59:56,408 - ERROR - 
All the 135 fits failed.
It is very likely that your model is misconfigured.
You can try to debug the error by setting error_score='raise'.

Below are more details about the failures:
--------------------------------------------------------------------------------
108 fits failed with the following error:
Traceback (most recent call last):
  File "C:\Users\Akash\AppData\Local\Programs\Python\Python311\Lib\site-packages\sklearn\model_selection\_validation.py", line 732, in _fit_and_score
    estimator.fit(X_train, y_train, **fit_params)
  File "C:\Users\Akash\AppData\Local\Programs\Python\Python311\Lib\site-packages\sklearn\base.py", line 1151, in wrapper
    return fit_method(estimator, *args, **kwargs)
           ^^^^^^^^^^^^^^^^^^^^^^^^^^^^^^^^^^^^^^
  File "C:\Users\Akash\AppData\Local\Programs\Python\Python311\Lib\site-packages\sklearn\ensemble\_forest.py", line 348, in fit
    X, y = self._validate_data(
           ^^^^^^^^^^^^^^^^^^^^
  File "C:\Users\Akash\AppData\Local\Programs\Python\Python311\Lib\site-packages\sklearn\base.py", line 621, in _validate_data
    X, y = check_X_y(X, y, **check_params)
           ^^^^^^^^^^^^^^^^^^^^^^^^^^^^^^^
  File "C:\Users\Akash\AppData\Local\Programs\Python\Python311\Lib\site-packages\sklearn\utils\validation.py", line 1147, in check_X_y
    X = check_array(
        ^^^^^^^^^^^^
  File "C:\Users\Akash\AppData\Local\Programs\Python\Python311\Lib\site-packages\sklearn\utils\validation.py", line 917, in check_array
    array = _asarray_with_order(array, order=order, dtype=dtype, xp=xp)
            ^^^^^^^^^^^^^^^^^^^^^^^^^^^^^^^^^^^^^^^^^^^^^^^^^^^^^^^^^^^
  File "C:\Users\Akash\AppData\Local\Programs\Python\Python311\Lib\site-packages\sklearn\utils\_array_api.py", line 380, in _asarray_with_order
    array = numpy.asarray(array, order=order, dtype=dtype)
            ^^^^^^^^^^^^^^^^^^^^^^^^^^^^^^^^^^^^^^^^^^^^^^
  File "C:\Users\Akash\AppData\Local\Programs\Python\Python311\Lib\site-packages\pandas\core\generic.py", line 1998, in __array__
    arr = np.asarray(values, dtype=dtype)
          ^^^^^^^^^^^^^^^^^^^^^^^^^^^^^^^
ValueError: could not convert string to float: ' Simulation'

--------------------------------------------------------------------------------
27 fits failed with the following error:
Traceback (most recent call last):
  File "C:\Users\Akash\AppData\Local\Programs\Python\Python311\Lib\site-packages\sklearn\model_selection\_validation.py", line 732, in _fit_and_score
    estimator.fit(X_train, y_train, **fit_params)
  File "C:\Users\Akash\AppData\Local\Programs\Python\Python311\Lib\site-packages\sklearn\base.py", line 1151, in wrapper
    return fit_method(estimator, *args, **kwargs)
           ^^^^^^^^^^^^^^^^^^^^^^^^^^^^^^^^^^^^^^
  File "C:\Users\Akash\AppData\Local\Programs\Python\Python311\Lib\site-packages\sklearn\ensemble\_forest.py", line 348, in fit
    X, y = self._validate_data(
           ^^^^^^^^^^^^^^^^^^^^
  File "C:\Users\Akash\AppData\Local\Programs\Python\Python311\Lib\site-packages\sklearn\base.py", line 621, in _validate_data
    X, y = check_X_y(X, y, **check_params)
           ^^^^^^^^^^^^^^^^^^^^^^^^^^^^^^^
  File "C:\Users\Akash\AppData\Local\Programs\Python\Python311\Lib\site-packages\sklearn\utils\validation.py", line 1147, in check_X_y
    X = check_array(
        ^^^^^^^^^^^^
  File "C:\Users\Akash\AppData\Local\Programs\Python\Python311\Lib\site-packages\sklearn\utils\validation.py", line 917, in check_array
    array = _asarray_with_order(array, order=order, dtype=dtype, xp=xp)
            ^^^^^^^^^^^^^^^^^^^^^^^^^^^^^^^^^^^^^^^^^^^^^^^^^^^^^^^^^^^
  File "C:\Users\Akash\AppData\Local\Programs\Python\Python311\Lib\site-packages\sklearn\utils\_array_api.py", line 380, in _asarray_with_order
    array = numpy.asarray(array, order=order, dtype=dtype)
            ^^^^^^^^^^^^^^^^^^^^^^^^^^^^^^^^^^^^^^^^^^^^^^
  File "C:\Users\Akash\AppData\Local\Programs\Python\Python311\Lib\site-packages\pandas\core\generic.py", line 1998, in __array__
    arr = np.asarray(values, dtype=dtype)
          ^^^^^^^^^^^^^^^^^^^^^^^^^^^^^^^
ValueError: could not convert string to float: ' Useful'

2023-09-14 13:00:16,465 - ERROR - 
All the 135 fits failed.
It is very likely that your model is misconfigured.
You can try to debug the error by setting error_score='raise'.

Below are more details about the failures:
--------------------------------------------------------------------------------
108 fits failed with the following error:
Traceback (most recent call last):
  File "C:\Users\Akash\AppData\Local\Programs\Python\Python311\Lib\site-packages\sklearn\model_selection\_validation.py", line 732, in _fit_and_score
    estimator.fit(X_train, y_train, **fit_params)
  File "C:\Users\Akash\AppData\Local\Programs\Python\Python311\Lib\site-packages\sklearn\base.py", line 1151, in wrapper
    return fit_method(estimator, *args, **kwargs)
           ^^^^^^^^^^^^^^^^^^^^^^^^^^^^^^^^^^^^^^
  File "C:\Users\Akash\AppData\Local\Programs\Python\Python311\Lib\site-packages\sklearn\ensemble\_forest.py", line 348, in fit
    X, y = self._validate_data(
           ^^^^^^^^^^^^^^^^^^^^
  File "C:\Users\Akash\AppData\Local\Programs\Python\Python311\Lib\site-packages\sklearn\base.py", line 621, in _validate_data
    X, y = check_X_y(X, y, **check_params)
           ^^^^^^^^^^^^^^^^^^^^^^^^^^^^^^^
  File "C:\Users\Akash\AppData\Local\Programs\Python\Python311\Lib\site-packages\sklearn\utils\validation.py", line 1147, in check_X_y
    X = check_array(
        ^^^^^^^^^^^^
  File "C:\Users\Akash\AppData\Local\Programs\Python\Python311\Lib\site-packages\sklearn\utils\validation.py", line 917, in check_array
    array = _asarray_with_order(array, order=order, dtype=dtype, xp=xp)
            ^^^^^^^^^^^^^^^^^^^^^^^^^^^^^^^^^^^^^^^^^^^^^^^^^^^^^^^^^^^
  File "C:\Users\Akash\AppData\Local\Programs\Python\Python311\Lib\site-packages\sklearn\utils\_array_api.py", line 380, in _asarray_with_order
    array = numpy.asarray(array, order=order, dtype=dtype)
            ^^^^^^^^^^^^^^^^^^^^^^^^^^^^^^^^^^^^^^^^^^^^^^
  File "C:\Users\Akash\AppData\Local\Programs\Python\Python311\Lib\site-packages\pandas\core\generic.py", line 1998, in __array__
    arr = np.asarray(values, dtype=dtype)
          ^^^^^^^^^^^^^^^^^^^^^^^^^^^^^^^
ValueError: could not convert string to float: ' Simulation'

--------------------------------------------------------------------------------
27 fits failed with the following error:
Traceback (most recent call last):
  File "C:\Users\Akash\AppData\Local\Programs\Python\Python311\Lib\site-packages\sklearn\model_selection\_validation.py", line 732, in _fit_and_score
    estimator.fit(X_train, y_train, **fit_params)
  File "C:\Users\Akash\AppData\Local\Programs\Python\Python311\Lib\site-packages\sklearn\base.py", line 1151, in wrapper
    return fit_method(estimator, *args, **kwargs)
           ^^^^^^^^^^^^^^^^^^^^^^^^^^^^^^^^^^^^^^
  File "C:\Users\Akash\AppData\Local\Programs\Python\Python311\Lib\site-packages\sklearn\ensemble\_forest.py", line 348, in fit
    X, y = self._validate_data(
           ^^^^^^^^^^^^^^^^^^^^
  File "C:\Users\Akash\AppData\Local\Programs\Python\Python311\Lib\site-packages\sklearn\base.py", line 621, in _validate_data
    X, y = check_X_y(X, y, **check_params)
           ^^^^^^^^^^^^^^^^^^^^^^^^^^^^^^^
  File "C:\Users\Akash\AppData\Local\Programs\Python\Python311\Lib\site-packages\sklearn\utils\validation.py", line 1147, in check_X_y
    X = check_array(
        ^^^^^^^^^^^^
  File "C:\Users\Akash\AppData\Local\Programs\Python\Python311\Lib\site-packages\sklearn\utils\validation.py", line 917, in check_array
    array = _asarray_with_order(array, order=order, dtype=dtype, xp=xp)
            ^^^^^^^^^^^^^^^^^^^^^^^^^^^^^^^^^^^^^^^^^^^^^^^^^^^^^^^^^^^
  File "C:\Users\Akash\AppData\Local\Programs\Python\Python311\Lib\site-packages\sklearn\utils\_array_api.py", line 380, in _asarray_with_order
    array = numpy.asarray(array, order=order, dtype=dtype)
            ^^^^^^^^^^^^^^^^^^^^^^^^^^^^^^^^^^^^^^^^^^^^^^
  File "C:\Users\Akash\AppData\Local\Programs\Python\Python311\Lib\site-packages\pandas\core\generic.py", line 1998, in __array__
    arr = np.asarray(values, dtype=dtype)
          ^^^^^^^^^^^^^^^^^^^^^^^^^^^^^^^
ValueError: could not convert string to float: ' Useful'

2023-09-14 13:00:36,144 - ERROR - 
All the 135 fits failed.
It is very likely that your model is misconfigured.
You can try to debug the error by setting error_score='raise'.

Below are more details about the failures:
--------------------------------------------------------------------------------
108 fits failed with the following error:
Traceback (most recent call last):
  File "C:\Users\Akash\AppData\Local\Programs\Python\Python311\Lib\site-packages\sklearn\model_selection\_validation.py", line 732, in _fit_and_score
    estimator.fit(X_train, y_train, **fit_params)
  File "C:\Users\Akash\AppData\Local\Programs\Python\Python311\Lib\site-packages\sklearn\base.py", line 1151, in wrapper
    return fit_method(estimator, *args, **kwargs)
           ^^^^^^^^^^^^^^^^^^^^^^^^^^^^^^^^^^^^^^
  File "C:\Users\Akash\AppData\Local\Programs\Python\Python311\Lib\site-packages\sklearn\ensemble\_forest.py", line 348, in fit
    X, y = self._validate_data(
           ^^^^^^^^^^^^^^^^^^^^
  File "C:\Users\Akash\AppData\Local\Programs\Python\Python311\Lib\site-packages\sklearn\base.py", line 621, in _validate_data
    X, y = check_X_y(X, y, **check_params)
           ^^^^^^^^^^^^^^^^^^^^^^^^^^^^^^^
  File "C:\Users\Akash\AppData\Local\Programs\Python\Python311\Lib\site-packages\sklearn\utils\validation.py", line 1147, in check_X_y
    X = check_array(
        ^^^^^^^^^^^^
  File "C:\Users\Akash\AppData\Local\Programs\Python\Python311\Lib\site-packages\sklearn\utils\validation.py", line 917, in check_array
    array = _asarray_with_order(array, order=order, dtype=dtype, xp=xp)
            ^^^^^^^^^^^^^^^^^^^^^^^^^^^^^^^^^^^^^^^^^^^^^^^^^^^^^^^^^^^
  File "C:\Users\Akash\AppData\Local\Programs\Python\Python311\Lib\site-packages\sklearn\utils\_array_api.py", line 380, in _asarray_with_order
    array = numpy.asarray(array, order=order, dtype=dtype)
            ^^^^^^^^^^^^^^^^^^^^^^^^^^^^^^^^^^^^^^^^^^^^^^
  File "C:\Users\Akash\AppData\Local\Programs\Python\Python311\Lib\site-packages\pandas\core\generic.py", line 1998, in __array__
    arr = np.asarray(values, dtype=dtype)
          ^^^^^^^^^^^^^^^^^^^^^^^^^^^^^^^
ValueError: could not convert string to float: ' Simulation'

--------------------------------------------------------------------------------
27 fits failed with the following error:
Traceback (most recent call last):
  File "C:\Users\Akash\AppData\Local\Programs\Python\Python311\Lib\site-packages\sklearn\model_selection\_validation.py", line 732, in _fit_and_score
    estimator.fit(X_train, y_train, **fit_params)
  File "C:\Users\Akash\AppData\Local\Programs\Python\Python311\Lib\site-packages\sklearn\base.py", line 1151, in wrapper
    return fit_method(estimator, *args, **kwargs)
           ^^^^^^^^^^^^^^^^^^^^^^^^^^^^^^^^^^^^^^
  File "C:\Users\Akash\AppData\Local\Programs\Python\Python311\Lib\site-packages\sklearn\ensemble\_forest.py", line 348, in fit
    X, y = self._validate_data(
           ^^^^^^^^^^^^^^^^^^^^
  File "C:\Users\Akash\AppData\Local\Programs\Python\Python311\Lib\site-packages\sklearn\base.py", line 621, in _validate_data
    X, y = check_X_y(X, y, **check_params)
           ^^^^^^^^^^^^^^^^^^^^^^^^^^^^^^^
  File "C:\Users\Akash\AppData\Local\Programs\Python\Python311\Lib\site-packages\sklearn\utils\validation.py", line 1147, in check_X_y
    X = check_array(
        ^^^^^^^^^^^^
  File "C:\Users\Akash\AppData\Local\Programs\Python\Python311\Lib\site-packages\sklearn\utils\validation.py", line 917, in check_array
    array = _asarray_with_order(array, order=order, dtype=dtype, xp=xp)
            ^^^^^^^^^^^^^^^^^^^^^^^^^^^^^^^^^^^^^^^^^^^^^^^^^^^^^^^^^^^
  File "C:\Users\Akash\AppData\Local\Programs\Python\Python311\Lib\site-packages\sklearn\utils\_array_api.py", line 380, in _asarray_with_order
    array = numpy.asarray(array, order=order, dtype=dtype)
            ^^^^^^^^^^^^^^^^^^^^^^^^^^^^^^^^^^^^^^^^^^^^^^
  File "C:\Users\Akash\AppData\Local\Programs\Python\Python311\Lib\site-packages\pandas\core\generic.py", line 1998, in __array__
    arr = np.asarray(values, dtype=dtype)
          ^^^^^^^^^^^^^^^^^^^^^^^^^^^^^^^
ValueError: could not convert string to float: ' Useful'

2023-09-14 13:00:56,062 - ERROR - 
All the 135 fits failed.
It is very likely that your model is misconfigured.
You can try to debug the error by setting error_score='raise'.

Below are more details about the failures:
--------------------------------------------------------------------------------
108 fits failed with the following error:
Traceback (most recent call last):
  File "C:\Users\Akash\AppData\Local\Programs\Python\Python311\Lib\site-packages\sklearn\model_selection\_validation.py", line 732, in _fit_and_score
    estimator.fit(X_train, y_train, **fit_params)
  File "C:\Users\Akash\AppData\Local\Programs\Python\Python311\Lib\site-packages\sklearn\base.py", line 1151, in wrapper
    return fit_method(estimator, *args, **kwargs)
           ^^^^^^^^^^^^^^^^^^^^^^^^^^^^^^^^^^^^^^
  File "C:\Users\Akash\AppData\Local\Programs\Python\Python311\Lib\site-packages\sklearn\ensemble\_forest.py", line 348, in fit
    X, y = self._validate_data(
           ^^^^^^^^^^^^^^^^^^^^
  File "C:\Users\Akash\AppData\Local\Programs\Python\Python311\Lib\site-packages\sklearn\base.py", line 621, in _validate_data
    X, y = check_X_y(X, y, **check_params)
           ^^^^^^^^^^^^^^^^^^^^^^^^^^^^^^^
  File "C:\Users\Akash\AppData\Local\Programs\Python\Python311\Lib\site-packages\sklearn\utils\validation.py", line 1147, in check_X_y
    X = check_array(
        ^^^^^^^^^^^^
  File "C:\Users\Akash\AppData\Local\Programs\Python\Python311\Lib\site-packages\sklearn\utils\validation.py", line 917, in check_array
    array = _asarray_with_order(array, order=order, dtype=dtype, xp=xp)
            ^^^^^^^^^^^^^^^^^^^^^^^^^^^^^^^^^^^^^^^^^^^^^^^^^^^^^^^^^^^
  File "C:\Users\Akash\AppData\Local\Programs\Python\Python311\Lib\site-packages\sklearn\utils\_array_api.py", line 380, in _asarray_with_order
    array = numpy.asarray(array, order=order, dtype=dtype)
            ^^^^^^^^^^^^^^^^^^^^^^^^^^^^^^^^^^^^^^^^^^^^^^
  File "C:\Users\Akash\AppData\Local\Programs\Python\Python311\Lib\site-packages\pandas\core\generic.py", line 1998, in __array__
    arr = np.asarray(values, dtype=dtype)
          ^^^^^^^^^^^^^^^^^^^^^^^^^^^^^^^
ValueError: could not convert string to float: ' Simulation'

--------------------------------------------------------------------------------
27 fits failed with the following error:
Traceback (most recent call last):
  File "C:\Users\Akash\AppData\Local\Programs\Python\Python311\Lib\site-packages\sklearn\model_selection\_validation.py", line 732, in _fit_and_score
    estimator.fit(X_train, y_train, **fit_params)
  File "C:\Users\Akash\AppData\Local\Programs\Python\Python311\Lib\site-packages\sklearn\base.py", line 1151, in wrapper
    return fit_method(estimator, *args, **kwargs)
           ^^^^^^^^^^^^^^^^^^^^^^^^^^^^^^^^^^^^^^
  File "C:\Users\Akash\AppData\Local\Programs\Python\Python311\Lib\site-packages\sklearn\ensemble\_forest.py", line 348, in fit
    X, y = self._validate_data(
           ^^^^^^^^^^^^^^^^^^^^
  File "C:\Users\Akash\AppData\Local\Programs\Python\Python311\Lib\site-packages\sklearn\base.py", line 621, in _validate_data
    X, y = check_X_y(X, y, **check_params)
           ^^^^^^^^^^^^^^^^^^^^^^^^^^^^^^^
  File "C:\Users\Akash\AppData\Local\Programs\Python\Python311\Lib\site-packages\sklearn\utils\validation.py", line 1147, in check_X_y
    X = check_array(
        ^^^^^^^^^^^^
  File "C:\Users\Akash\AppData\Local\Programs\Python\Python311\Lib\site-packages\sklearn\utils\validation.py", line 917, in check_array
    array = _asarray_with_order(array, order=order, dtype=dtype, xp=xp)
            ^^^^^^^^^^^^^^^^^^^^^^^^^^^^^^^^^^^^^^^^^^^^^^^^^^^^^^^^^^^
  File "C:\Users\Akash\AppData\Local\Programs\Python\Python311\Lib\site-packages\sklearn\utils\_array_api.py", line 380, in _asarray_with_order
    array = numpy.asarray(array, order=order, dtype=dtype)
            ^^^^^^^^^^^^^^^^^^^^^^^^^^^^^^^^^^^^^^^^^^^^^^
  File "C:\Users\Akash\AppData\Local\Programs\Python\Python311\Lib\site-packages\pandas\core\generic.py", line 1998, in __array__
    arr = np.asarray(values, dtype=dtype)
          ^^^^^^^^^^^^^^^^^^^^^^^^^^^^^^^
ValueError: could not convert string to float: ' Useful'

2023-09-14 13:01:38,557 - ERROR - 
All the 135 fits failed.
It is very likely that your model is misconfigured.
You can try to debug the error by setting error_score='raise'.

Below are more details about the failures:
--------------------------------------------------------------------------------
108 fits failed with the following error:
Traceback (most recent call last):
  File "C:\Users\Akash\AppData\Local\Programs\Python\Python311\Lib\site-packages\sklearn\model_selection\_validation.py", line 732, in _fit_and_score
    estimator.fit(X_train, y_train, **fit_params)
  File "C:\Users\Akash\AppData\Local\Programs\Python\Python311\Lib\site-packages\sklearn\base.py", line 1151, in wrapper
    return fit_method(estimator, *args, **kwargs)
           ^^^^^^^^^^^^^^^^^^^^^^^^^^^^^^^^^^^^^^
  File "C:\Users\Akash\AppData\Local\Programs\Python\Python311\Lib\site-packages\sklearn\ensemble\_forest.py", line 348, in fit
    X, y = self._validate_data(
           ^^^^^^^^^^^^^^^^^^^^
  File "C:\Users\Akash\AppData\Local\Programs\Python\Python311\Lib\site-packages\sklearn\base.py", line 621, in _validate_data
    X, y = check_X_y(X, y, **check_params)
           ^^^^^^^^^^^^^^^^^^^^^^^^^^^^^^^
  File "C:\Users\Akash\AppData\Local\Programs\Python\Python311\Lib\site-packages\sklearn\utils\validation.py", line 1147, in check_X_y
    X = check_array(
        ^^^^^^^^^^^^
  File "C:\Users\Akash\AppData\Local\Programs\Python\Python311\Lib\site-packages\sklearn\utils\validation.py", line 917, in check_array
    array = _asarray_with_order(array, order=order, dtype=dtype, xp=xp)
            ^^^^^^^^^^^^^^^^^^^^^^^^^^^^^^^^^^^^^^^^^^^^^^^^^^^^^^^^^^^
  File "C:\Users\Akash\AppData\Local\Programs\Python\Python311\Lib\site-packages\sklearn\utils\_array_api.py", line 380, in _asarray_with_order
    array = numpy.asarray(array, order=order, dtype=dtype)
            ^^^^^^^^^^^^^^^^^^^^^^^^^^^^^^^^^^^^^^^^^^^^^^
  File "C:\Users\Akash\AppData\Local\Programs\Python\Python311\Lib\site-packages\pandas\core\generic.py", line 1998, in __array__
    arr = np.asarray(values, dtype=dtype)
          ^^^^^^^^^^^^^^^^^^^^^^^^^^^^^^^
ValueError: could not convert string to float: ' Simulation'

--------------------------------------------------------------------------------
27 fits failed with the following error:
Traceback (most recent call last):
  File "C:\Users\Akash\AppData\Local\Programs\Python\Python311\Lib\site-packages\sklearn\model_selection\_validation.py", line 732, in _fit_and_score
    estimator.fit(X_train, y_train, **fit_params)
  File "C:\Users\Akash\AppData\Local\Programs\Python\Python311\Lib\site-packages\sklearn\base.py", line 1151, in wrapper
    return fit_method(estimator, *args, **kwargs)
           ^^^^^^^^^^^^^^^^^^^^^^^^^^^^^^^^^^^^^^
  File "C:\Users\Akash\AppData\Local\Programs\Python\Python311\Lib\site-packages\sklearn\ensemble\_forest.py", line 348, in fit
    X, y = self._validate_data(
           ^^^^^^^^^^^^^^^^^^^^
  File "C:\Users\Akash\AppData\Local\Programs\Python\Python311\Lib\site-packages\sklearn\base.py", line 621, in _validate_data
    X, y = check_X_y(X, y, **check_params)
           ^^^^^^^^^^^^^^^^^^^^^^^^^^^^^^^
  File "C:\Users\Akash\AppData\Local\Programs\Python\Python311\Lib\site-packages\sklearn\utils\validation.py", line 1147, in check_X_y
    X = check_array(
        ^^^^^^^^^^^^
  File "C:\Users\Akash\AppData\Local\Programs\Python\Python311\Lib\site-packages\sklearn\utils\validation.py", line 917, in check_array
    array = _asarray_with_order(array, order=order, dtype=dtype, xp=xp)
            ^^^^^^^^^^^^^^^^^^^^^^^^^^^^^^^^^^^^^^^^^^^^^^^^^^^^^^^^^^^
  File "C:\Users\Akash\AppData\Local\Programs\Python\Python311\Lib\site-packages\sklearn\utils\_array_api.py", line 380, in _asarray_with_order
    array = numpy.asarray(array, order=order, dtype=dtype)
            ^^^^^^^^^^^^^^^^^^^^^^^^^^^^^^^^^^^^^^^^^^^^^^
  File "C:\Users\Akash\AppData\Local\Programs\Python\Python311\Lib\site-packages\pandas\core\generic.py", line 1998, in __array__
    arr = np.asarray(values, dtype=dtype)
          ^^^^^^^^^^^^^^^^^^^^^^^^^^^^^^^
ValueError: could not convert string to float: ' Useful'

2023-09-14 13:01:59,436 - ERROR - 
All the 135 fits failed.
It is very likely that your model is misconfigured.
You can try to debug the error by setting error_score='raise'.

Below are more details about the failures:
--------------------------------------------------------------------------------
108 fits failed with the following error:
Traceback (most recent call last):
  File "C:\Users\Akash\AppData\Local\Programs\Python\Python311\Lib\site-packages\sklearn\model_selection\_validation.py", line 732, in _fit_and_score
    estimator.fit(X_train, y_train, **fit_params)
  File "C:\Users\Akash\AppData\Local\Programs\Python\Python311\Lib\site-packages\sklearn\base.py", line 1151, in wrapper
    return fit_method(estimator, *args, **kwargs)
           ^^^^^^^^^^^^^^^^^^^^^^^^^^^^^^^^^^^^^^
  File "C:\Users\Akash\AppData\Local\Programs\Python\Python311\Lib\site-packages\sklearn\ensemble\_forest.py", line 348, in fit
    X, y = self._validate_data(
           ^^^^^^^^^^^^^^^^^^^^
  File "C:\Users\Akash\AppData\Local\Programs\Python\Python311\Lib\site-packages\sklearn\base.py", line 621, in _validate_data
    X, y = check_X_y(X, y, **check_params)
           ^^^^^^^^^^^^^^^^^^^^^^^^^^^^^^^
  File "C:\Users\Akash\AppData\Local\Programs\Python\Python311\Lib\site-packages\sklearn\utils\validation.py", line 1147, in check_X_y
    X = check_array(
        ^^^^^^^^^^^^
  File "C:\Users\Akash\AppData\Local\Programs\Python\Python311\Lib\site-packages\sklearn\utils\validation.py", line 917, in check_array
    array = _asarray_with_order(array, order=order, dtype=dtype, xp=xp)
            ^^^^^^^^^^^^^^^^^^^^^^^^^^^^^^^^^^^^^^^^^^^^^^^^^^^^^^^^^^^
  File "C:\Users\Akash\AppData\Local\Programs\Python\Python311\Lib\site-packages\sklearn\utils\_array_api.py", line 380, in _asarray_with_order
    array = numpy.asarray(array, order=order, dtype=dtype)
            ^^^^^^^^^^^^^^^^^^^^^^^^^^^^^^^^^^^^^^^^^^^^^^
  File "C:\Users\Akash\AppData\Local\Programs\Python\Python311\Lib\site-packages\pandas\core\generic.py", line 1998, in __array__
    arr = np.asarray(values, dtype=dtype)
          ^^^^^^^^^^^^^^^^^^^^^^^^^^^^^^^
ValueError: could not convert string to float: ' Simulation'

--------------------------------------------------------------------------------
27 fits failed with the following error:
Traceback (most recent call last):
  File "C:\Users\Akash\AppData\Local\Programs\Python\Python311\Lib\site-packages\sklearn\model_selection\_validation.py", line 732, in _fit_and_score
    estimator.fit(X_train, y_train, **fit_params)
  File "C:\Users\Akash\AppData\Local\Programs\Python\Python311\Lib\site-packages\sklearn\base.py", line 1151, in wrapper
    return fit_method(estimator, *args, **kwargs)
           ^^^^^^^^^^^^^^^^^^^^^^^^^^^^^^^^^^^^^^
  File "C:\Users\Akash\AppData\Local\Programs\Python\Python311\Lib\site-packages\sklearn\ensemble\_forest.py", line 348, in fit
    X, y = self._validate_data(
           ^^^^^^^^^^^^^^^^^^^^
  File "C:\Users\Akash\AppData\Local\Programs\Python\Python311\Lib\site-packages\sklearn\base.py", line 621, in _validate_data
    X, y = check_X_y(X, y, **check_params)
           ^^^^^^^^^^^^^^^^^^^^^^^^^^^^^^^
  File "C:\Users\Akash\AppData\Local\Programs\Python\Python311\Lib\site-packages\sklearn\utils\validation.py", line 1147, in check_X_y
    X = check_array(
        ^^^^^^^^^^^^
  File "C:\Users\Akash\AppData\Local\Programs\Python\Python311\Lib\site-packages\sklearn\utils\validation.py", line 917, in check_array
    array = _asarray_with_order(array, order=order, dtype=dtype, xp=xp)
            ^^^^^^^^^^^^^^^^^^^^^^^^^^^^^^^^^^^^^^^^^^^^^^^^^^^^^^^^^^^
  File "C:\Users\Akash\AppData\Local\Programs\Python\Python311\Lib\site-packages\sklearn\utils\_array_api.py", line 380, in _asarray_with_order
    array = numpy.asarray(array, order=order, dtype=dtype)
            ^^^^^^^^^^^^^^^^^^^^^^^^^^^^^^^^^^^^^^^^^^^^^^
  File "C:\Users\Akash\AppData\Local\Programs\Python\Python311\Lib\site-packages\pandas\core\generic.py", line 1998, in __array__
    arr = np.asarray(values, dtype=dtype)
          ^^^^^^^^^^^^^^^^^^^^^^^^^^^^^^^
ValueError: could not convert string to float: ' Useful'

2023-09-14 13:02:20,029 - ERROR - 
All the 135 fits failed.
It is very likely that your model is misconfigured.
You can try to debug the error by setting error_score='raise'.

Below are more details about the failures:
--------------------------------------------------------------------------------
108 fits failed with the following error:
Traceback (most recent call last):
  File "C:\Users\Akash\AppData\Local\Programs\Python\Python311\Lib\site-packages\sklearn\model_selection\_validation.py", line 732, in _fit_and_score
    estimator.fit(X_train, y_train, **fit_params)
  File "C:\Users\Akash\AppData\Local\Programs\Python\Python311\Lib\site-packages\sklearn\base.py", line 1151, in wrapper
    return fit_method(estimator, *args, **kwargs)
           ^^^^^^^^^^^^^^^^^^^^^^^^^^^^^^^^^^^^^^
  File "C:\Users\Akash\AppData\Local\Programs\Python\Python311\Lib\site-packages\sklearn\ensemble\_forest.py", line 348, in fit
    X, y = self._validate_data(
           ^^^^^^^^^^^^^^^^^^^^
  File "C:\Users\Akash\AppData\Local\Programs\Python\Python311\Lib\site-packages\sklearn\base.py", line 621, in _validate_data
    X, y = check_X_y(X, y, **check_params)
           ^^^^^^^^^^^^^^^^^^^^^^^^^^^^^^^
  File "C:\Users\Akash\AppData\Local\Programs\Python\Python311\Lib\site-packages\sklearn\utils\validation.py", line 1147, in check_X_y
    X = check_array(
        ^^^^^^^^^^^^
  File "C:\Users\Akash\AppData\Local\Programs\Python\Python311\Lib\site-packages\sklearn\utils\validation.py", line 917, in check_array
    array = _asarray_with_order(array, order=order, dtype=dtype, xp=xp)
            ^^^^^^^^^^^^^^^^^^^^^^^^^^^^^^^^^^^^^^^^^^^^^^^^^^^^^^^^^^^
  File "C:\Users\Akash\AppData\Local\Programs\Python\Python311\Lib\site-packages\sklearn\utils\_array_api.py", line 380, in _asarray_with_order
    array = numpy.asarray(array, order=order, dtype=dtype)
            ^^^^^^^^^^^^^^^^^^^^^^^^^^^^^^^^^^^^^^^^^^^^^^
  File "C:\Users\Akash\AppData\Local\Programs\Python\Python311\Lib\site-packages\pandas\core\generic.py", line 1998, in __array__
    arr = np.asarray(values, dtype=dtype)
          ^^^^^^^^^^^^^^^^^^^^^^^^^^^^^^^
ValueError: could not convert string to float: ' Simulation'

--------------------------------------------------------------------------------
27 fits failed with the following error:
Traceback (most recent call last):
  File "C:\Users\Akash\AppData\Local\Programs\Python\Python311\Lib\site-packages\sklearn\model_selection\_validation.py", line 732, in _fit_and_score
    estimator.fit(X_train, y_train, **fit_params)
  File "C:\Users\Akash\AppData\Local\Programs\Python\Python311\Lib\site-packages\sklearn\base.py", line 1151, in wrapper
    return fit_method(estimator, *args, **kwargs)
           ^^^^^^^^^^^^^^^^^^^^^^^^^^^^^^^^^^^^^^
  File "C:\Users\Akash\AppData\Local\Programs\Python\Python311\Lib\site-packages\sklearn\ensemble\_forest.py", line 348, in fit
    X, y = self._validate_data(
           ^^^^^^^^^^^^^^^^^^^^
  File "C:\Users\Akash\AppData\Local\Programs\Python\Python311\Lib\site-packages\sklearn\base.py", line 621, in _validate_data
    X, y = check_X_y(X, y, **check_params)
           ^^^^^^^^^^^^^^^^^^^^^^^^^^^^^^^
  File "C:\Users\Akash\AppData\Local\Programs\Python\Python311\Lib\site-packages\sklearn\utils\validation.py", line 1147, in check_X_y
    X = check_array(
        ^^^^^^^^^^^^
  File "C:\Users\Akash\AppData\Local\Programs\Python\Python311\Lib\site-packages\sklearn\utils\validation.py", line 917, in check_array
    array = _asarray_with_order(array, order=order, dtype=dtype, xp=xp)
            ^^^^^^^^^^^^^^^^^^^^^^^^^^^^^^^^^^^^^^^^^^^^^^^^^^^^^^^^^^^
  File "C:\Users\Akash\AppData\Local\Programs\Python\Python311\Lib\site-packages\sklearn\utils\_array_api.py", line 380, in _asarray_with_order
    array = numpy.asarray(array, order=order, dtype=dtype)
            ^^^^^^^^^^^^^^^^^^^^^^^^^^^^^^^^^^^^^^^^^^^^^^
  File "C:\Users\Akash\AppData\Local\Programs\Python\Python311\Lib\site-packages\pandas\core\generic.py", line 1998, in __array__
    arr = np.asarray(values, dtype=dtype)
          ^^^^^^^^^^^^^^^^^^^^^^^^^^^^^^^
ValueError: could not convert string to float: ' Useful'

2023-09-14 13:02:42,440 - ERROR - 
All the 135 fits failed.
It is very likely that your model is misconfigured.
You can try to debug the error by setting error_score='raise'.

Below are more details about the failures:
--------------------------------------------------------------------------------
108 fits failed with the following error:
Traceback (most recent call last):
  File "C:\Users\Akash\AppData\Local\Programs\Python\Python311\Lib\site-packages\sklearn\model_selection\_validation.py", line 732, in _fit_and_score
    estimator.fit(X_train, y_train, **fit_params)
  File "C:\Users\Akash\AppData\Local\Programs\Python\Python311\Lib\site-packages\sklearn\base.py", line 1151, in wrapper
    return fit_method(estimator, *args, **kwargs)
           ^^^^^^^^^^^^^^^^^^^^^^^^^^^^^^^^^^^^^^
  File "C:\Users\Akash\AppData\Local\Programs\Python\Python311\Lib\site-packages\sklearn\ensemble\_forest.py", line 348, in fit
    X, y = self._validate_data(
           ^^^^^^^^^^^^^^^^^^^^
  File "C:\Users\Akash\AppData\Local\Programs\Python\Python311\Lib\site-packages\sklearn\base.py", line 621, in _validate_data
    X, y = check_X_y(X, y, **check_params)
           ^^^^^^^^^^^^^^^^^^^^^^^^^^^^^^^
  File "C:\Users\Akash\AppData\Local\Programs\Python\Python311\Lib\site-packages\sklearn\utils\validation.py", line 1147, in check_X_y
    X = check_array(
        ^^^^^^^^^^^^
  File "C:\Users\Akash\AppData\Local\Programs\Python\Python311\Lib\site-packages\sklearn\utils\validation.py", line 917, in check_array
    array = _asarray_with_order(array, order=order, dtype=dtype, xp=xp)
            ^^^^^^^^^^^^^^^^^^^^^^^^^^^^^^^^^^^^^^^^^^^^^^^^^^^^^^^^^^^
  File "C:\Users\Akash\AppData\Local\Programs\Python\Python311\Lib\site-packages\sklearn\utils\_array_api.py", line 380, in _asarray_with_order
    array = numpy.asarray(array, order=order, dtype=dtype)
            ^^^^^^^^^^^^^^^^^^^^^^^^^^^^^^^^^^^^^^^^^^^^^^
  File "C:\Users\Akash\AppData\Local\Programs\Python\Python311\Lib\site-packages\pandas\core\generic.py", line 1998, in __array__
    arr = np.asarray(values, dtype=dtype)
          ^^^^^^^^^^^^^^^^^^^^^^^^^^^^^^^
ValueError: could not convert string to float: ' Simulation'

--------------------------------------------------------------------------------
27 fits failed with the following error:
Traceback (most recent call last):
  File "C:\Users\Akash\AppData\Local\Programs\Python\Python311\Lib\site-packages\sklearn\model_selection\_validation.py", line 732, in _fit_and_score
    estimator.fit(X_train, y_train, **fit_params)
  File "C:\Users\Akash\AppData\Local\Programs\Python\Python311\Lib\site-packages\sklearn\base.py", line 1151, in wrapper
    return fit_method(estimator, *args, **kwargs)
           ^^^^^^^^^^^^^^^^^^^^^^^^^^^^^^^^^^^^^^
  File "C:\Users\Akash\AppData\Local\Programs\Python\Python311\Lib\site-packages\sklearn\ensemble\_forest.py", line 348, in fit
    X, y = self._validate_data(
           ^^^^^^^^^^^^^^^^^^^^
  File "C:\Users\Akash\AppData\Local\Programs\Python\Python311\Lib\site-packages\sklearn\base.py", line 621, in _validate_data
    X, y = check_X_y(X, y, **check_params)
           ^^^^^^^^^^^^^^^^^^^^^^^^^^^^^^^
  File "C:\Users\Akash\AppData\Local\Programs\Python\Python311\Lib\site-packages\sklearn\utils\validation.py", line 1147, in check_X_y
    X = check_array(
        ^^^^^^^^^^^^
  File "C:\Users\Akash\AppData\Local\Programs\Python\Python311\Lib\site-packages\sklearn\utils\validation.py", line 917, in check_array
    array = _asarray_with_order(array, order=order, dtype=dtype, xp=xp)
            ^^^^^^^^^^^^^^^^^^^^^^^^^^^^^^^^^^^^^^^^^^^^^^^^^^^^^^^^^^^
  File "C:\Users\Akash\AppData\Local\Programs\Python\Python311\Lib\site-packages\sklearn\utils\_array_api.py", line 380, in _asarray_with_order
    array = numpy.asarray(array, order=order, dtype=dtype)
            ^^^^^^^^^^^^^^^^^^^^^^^^^^^^^^^^^^^^^^^^^^^^^^
  File "C:\Users\Akash\AppData\Local\Programs\Python\Python311\Lib\site-packages\pandas\core\generic.py", line 1998, in __array__
    arr = np.asarray(values, dtype=dtype)
          ^^^^^^^^^^^^^^^^^^^^^^^^^^^^^^^
ValueError: could not convert string to float: ' Useful'

2023-09-14 13:03:03,236 - ERROR - 
All the 135 fits failed.
It is very likely that your model is misconfigured.
You can try to debug the error by setting error_score='raise'.

Below are more details about the failures:
--------------------------------------------------------------------------------
108 fits failed with the following error:
Traceback (most recent call last):
  File "C:\Users\Akash\AppData\Local\Programs\Python\Python311\Lib\site-packages\sklearn\model_selection\_validation.py", line 732, in _fit_and_score
    estimator.fit(X_train, y_train, **fit_params)
  File "C:\Users\Akash\AppData\Local\Programs\Python\Python311\Lib\site-packages\sklearn\base.py", line 1151, in wrapper
    return fit_method(estimator, *args, **kwargs)
           ^^^^^^^^^^^^^^^^^^^^^^^^^^^^^^^^^^^^^^
  File "C:\Users\Akash\AppData\Local\Programs\Python\Python311\Lib\site-packages\sklearn\ensemble\_forest.py", line 348, in fit
    X, y = self._validate_data(
           ^^^^^^^^^^^^^^^^^^^^
  File "C:\Users\Akash\AppData\Local\Programs\Python\Python311\Lib\site-packages\sklearn\base.py", line 621, in _validate_data
    X, y = check_X_y(X, y, **check_params)
           ^^^^^^^^^^^^^^^^^^^^^^^^^^^^^^^
  File "C:\Users\Akash\AppData\Local\Programs\Python\Python311\Lib\site-packages\sklearn\utils\validation.py", line 1147, in check_X_y
    X = check_array(
        ^^^^^^^^^^^^
  File "C:\Users\Akash\AppData\Local\Programs\Python\Python311\Lib\site-packages\sklearn\utils\validation.py", line 917, in check_array
    array = _asarray_with_order(array, order=order, dtype=dtype, xp=xp)
            ^^^^^^^^^^^^^^^^^^^^^^^^^^^^^^^^^^^^^^^^^^^^^^^^^^^^^^^^^^^
  File "C:\Users\Akash\AppData\Local\Programs\Python\Python311\Lib\site-packages\sklearn\utils\_array_api.py", line 380, in _asarray_with_order
    array = numpy.asarray(array, order=order, dtype=dtype)
            ^^^^^^^^^^^^^^^^^^^^^^^^^^^^^^^^^^^^^^^^^^^^^^
  File "C:\Users\Akash\AppData\Local\Programs\Python\Python311\Lib\site-packages\pandas\core\generic.py", line 1998, in __array__
    arr = np.asarray(values, dtype=dtype)
          ^^^^^^^^^^^^^^^^^^^^^^^^^^^^^^^
ValueError: could not convert string to float: ' Simulation'

--------------------------------------------------------------------------------
27 fits failed with the following error:
Traceback (most recent call last):
  File "C:\Users\Akash\AppData\Local\Programs\Python\Python311\Lib\site-packages\sklearn\model_selection\_validation.py", line 732, in _fit_and_score
    estimator.fit(X_train, y_train, **fit_params)
  File "C:\Users\Akash\AppData\Local\Programs\Python\Python311\Lib\site-packages\sklearn\base.py", line 1151, in wrapper
    return fit_method(estimator, *args, **kwargs)
           ^^^^^^^^^^^^^^^^^^^^^^^^^^^^^^^^^^^^^^
  File "C:\Users\Akash\AppData\Local\Programs\Python\Python311\Lib\site-packages\sklearn\ensemble\_forest.py", line 348, in fit
    X, y = self._validate_data(
           ^^^^^^^^^^^^^^^^^^^^
  File "C:\Users\Akash\AppData\Local\Programs\Python\Python311\Lib\site-packages\sklearn\base.py", line 621, in _validate_data
    X, y = check_X_y(X, y, **check_params)
           ^^^^^^^^^^^^^^^^^^^^^^^^^^^^^^^
  File "C:\Users\Akash\AppData\Local\Programs\Python\Python311\Lib\site-packages\sklearn\utils\validation.py", line 1147, in check_X_y
    X = check_array(
        ^^^^^^^^^^^^
  File "C:\Users\Akash\AppData\Local\Programs\Python\Python311\Lib\site-packages\sklearn\utils\validation.py", line 917, in check_array
    array = _asarray_with_order(array, order=order, dtype=dtype, xp=xp)
            ^^^^^^^^^^^^^^^^^^^^^^^^^^^^^^^^^^^^^^^^^^^^^^^^^^^^^^^^^^^
  File "C:\Users\Akash\AppData\Local\Programs\Python\Python311\Lib\site-packages\sklearn\utils\_array_api.py", line 380, in _asarray_with_order
    array = numpy.asarray(array, order=order, dtype=dtype)
            ^^^^^^^^^^^^^^^^^^^^^^^^^^^^^^^^^^^^^^^^^^^^^^
  File "C:\Users\Akash\AppData\Local\Programs\Python\Python311\Lib\site-packages\pandas\core\generic.py", line 1998, in __array__
    arr = np.asarray(values, dtype=dtype)
          ^^^^^^^^^^^^^^^^^^^^^^^^^^^^^^^
ValueError: could not convert string to float: ' Useful'

2023-09-14 13:03:23,128 - ERROR - 
All the 135 fits failed.
It is very likely that your model is misconfigured.
You can try to debug the error by setting error_score='raise'.

Below are more details about the failures:
--------------------------------------------------------------------------------
108 fits failed with the following error:
Traceback (most recent call last):
  File "C:\Users\Akash\AppData\Local\Programs\Python\Python311\Lib\site-packages\sklearn\model_selection\_validation.py", line 732, in _fit_and_score
    estimator.fit(X_train, y_train, **fit_params)
  File "C:\Users\Akash\AppData\Local\Programs\Python\Python311\Lib\site-packages\sklearn\base.py", line 1151, in wrapper
    return fit_method(estimator, *args, **kwargs)
           ^^^^^^^^^^^^^^^^^^^^^^^^^^^^^^^^^^^^^^
  File "C:\Users\Akash\AppData\Local\Programs\Python\Python311\Lib\site-packages\sklearn\ensemble\_forest.py", line 348, in fit
    X, y = self._validate_data(
           ^^^^^^^^^^^^^^^^^^^^
  File "C:\Users\Akash\AppData\Local\Programs\Python\Python311\Lib\site-packages\sklearn\base.py", line 621, in _validate_data
    X, y = check_X_y(X, y, **check_params)
           ^^^^^^^^^^^^^^^^^^^^^^^^^^^^^^^
  File "C:\Users\Akash\AppData\Local\Programs\Python\Python311\Lib\site-packages\sklearn\utils\validation.py", line 1147, in check_X_y
    X = check_array(
        ^^^^^^^^^^^^
  File "C:\Users\Akash\AppData\Local\Programs\Python\Python311\Lib\site-packages\sklearn\utils\validation.py", line 917, in check_array
    array = _asarray_with_order(array, order=order, dtype=dtype, xp=xp)
            ^^^^^^^^^^^^^^^^^^^^^^^^^^^^^^^^^^^^^^^^^^^^^^^^^^^^^^^^^^^
  File "C:\Users\Akash\AppData\Local\Programs\Python\Python311\Lib\site-packages\sklearn\utils\_array_api.py", line 380, in _asarray_with_order
    array = numpy.asarray(array, order=order, dtype=dtype)
            ^^^^^^^^^^^^^^^^^^^^^^^^^^^^^^^^^^^^^^^^^^^^^^
  File "C:\Users\Akash\AppData\Local\Programs\Python\Python311\Lib\site-packages\pandas\core\generic.py", line 1998, in __array__
    arr = np.asarray(values, dtype=dtype)
          ^^^^^^^^^^^^^^^^^^^^^^^^^^^^^^^
ValueError: could not convert string to float: ' Simulation'

--------------------------------------------------------------------------------
27 fits failed with the following error:
Traceback (most recent call last):
  File "C:\Users\Akash\AppData\Local\Programs\Python\Python311\Lib\site-packages\sklearn\model_selection\_validation.py", line 732, in _fit_and_score
    estimator.fit(X_train, y_train, **fit_params)
  File "C:\Users\Akash\AppData\Local\Programs\Python\Python311\Lib\site-packages\sklearn\base.py", line 1151, in wrapper
    return fit_method(estimator, *args, **kwargs)
           ^^^^^^^^^^^^^^^^^^^^^^^^^^^^^^^^^^^^^^
  File "C:\Users\Akash\AppData\Local\Programs\Python\Python311\Lib\site-packages\sklearn\ensemble\_forest.py", line 348, in fit
    X, y = self._validate_data(
           ^^^^^^^^^^^^^^^^^^^^
  File "C:\Users\Akash\AppData\Local\Programs\Python\Python311\Lib\site-packages\sklearn\base.py", line 621, in _validate_data
    X, y = check_X_y(X, y, **check_params)
           ^^^^^^^^^^^^^^^^^^^^^^^^^^^^^^^
  File "C:\Users\Akash\AppData\Local\Programs\Python\Python311\Lib\site-packages\sklearn\utils\validation.py", line 1147, in check_X_y
    X = check_array(
        ^^^^^^^^^^^^
  File "C:\Users\Akash\AppData\Local\Programs\Python\Python311\Lib\site-packages\sklearn\utils\validation.py", line 917, in check_array
    array = _asarray_with_order(array, order=order, dtype=dtype, xp=xp)
            ^^^^^^^^^^^^^^^^^^^^^^^^^^^^^^^^^^^^^^^^^^^^^^^^^^^^^^^^^^^
  File "C:\Users\Akash\AppData\Local\Programs\Python\Python311\Lib\site-packages\sklearn\utils\_array_api.py", line 380, in _asarray_with_order
    array = numpy.asarray(array, order=order, dtype=dtype)
            ^^^^^^^^^^^^^^^^^^^^^^^^^^^^^^^^^^^^^^^^^^^^^^
  File "C:\Users\Akash\AppData\Local\Programs\Python\Python311\Lib\site-packages\pandas\core\generic.py", line 1998, in __array__
    arr = np.asarray(values, dtype=dtype)
          ^^^^^^^^^^^^^^^^^^^^^^^^^^^^^^^
ValueError: could not convert string to float: ' Useful'

2023-09-14 13:03:43,347 - ERROR - 
All the 135 fits failed.
It is very likely that your model is misconfigured.
You can try to debug the error by setting error_score='raise'.

Below are more details about the failures:
--------------------------------------------------------------------------------
108 fits failed with the following error:
Traceback (most recent call last):
  File "C:\Users\Akash\AppData\Local\Programs\Python\Python311\Lib\site-packages\sklearn\model_selection\_validation.py", line 732, in _fit_and_score
    estimator.fit(X_train, y_train, **fit_params)
  File "C:\Users\Akash\AppData\Local\Programs\Python\Python311\Lib\site-packages\sklearn\base.py", line 1151, in wrapper
    return fit_method(estimator, *args, **kwargs)
           ^^^^^^^^^^^^^^^^^^^^^^^^^^^^^^^^^^^^^^
  File "C:\Users\Akash\AppData\Local\Programs\Python\Python311\Lib\site-packages\sklearn\ensemble\_forest.py", line 348, in fit
    X, y = self._validate_data(
           ^^^^^^^^^^^^^^^^^^^^
  File "C:\Users\Akash\AppData\Local\Programs\Python\Python311\Lib\site-packages\sklearn\base.py", line 621, in _validate_data
    X, y = check_X_y(X, y, **check_params)
           ^^^^^^^^^^^^^^^^^^^^^^^^^^^^^^^
  File "C:\Users\Akash\AppData\Local\Programs\Python\Python311\Lib\site-packages\sklearn\utils\validation.py", line 1147, in check_X_y
    X = check_array(
        ^^^^^^^^^^^^
  File "C:\Users\Akash\AppData\Local\Programs\Python\Python311\Lib\site-packages\sklearn\utils\validation.py", line 917, in check_array
    array = _asarray_with_order(array, order=order, dtype=dtype, xp=xp)
            ^^^^^^^^^^^^^^^^^^^^^^^^^^^^^^^^^^^^^^^^^^^^^^^^^^^^^^^^^^^
  File "C:\Users\Akash\AppData\Local\Programs\Python\Python311\Lib\site-packages\sklearn\utils\_array_api.py", line 380, in _asarray_with_order
    array = numpy.asarray(array, order=order, dtype=dtype)
            ^^^^^^^^^^^^^^^^^^^^^^^^^^^^^^^^^^^^^^^^^^^^^^
  File "C:\Users\Akash\AppData\Local\Programs\Python\Python311\Lib\site-packages\pandas\core\generic.py", line 1998, in __array__
    arr = np.asarray(values, dtype=dtype)
          ^^^^^^^^^^^^^^^^^^^^^^^^^^^^^^^
ValueError: could not convert string to float: ' Simulation'

--------------------------------------------------------------------------------
27 fits failed with the following error:
Traceback (most recent call last):
  File "C:\Users\Akash\AppData\Local\Programs\Python\Python311\Lib\site-packages\sklearn\model_selection\_validation.py", line 732, in _fit_and_score
    estimator.fit(X_train, y_train, **fit_params)
  File "C:\Users\Akash\AppData\Local\Programs\Python\Python311\Lib\site-packages\sklearn\base.py", line 1151, in wrapper
    return fit_method(estimator, *args, **kwargs)
           ^^^^^^^^^^^^^^^^^^^^^^^^^^^^^^^^^^^^^^
  File "C:\Users\Akash\AppData\Local\Programs\Python\Python311\Lib\site-packages\sklearn\ensemble\_forest.py", line 348, in fit
    X, y = self._validate_data(
           ^^^^^^^^^^^^^^^^^^^^
  File "C:\Users\Akash\AppData\Local\Programs\Python\Python311\Lib\site-packages\sklearn\base.py", line 621, in _validate_data
    X, y = check_X_y(X, y, **check_params)
           ^^^^^^^^^^^^^^^^^^^^^^^^^^^^^^^
  File "C:\Users\Akash\AppData\Local\Programs\Python\Python311\Lib\site-packages\sklearn\utils\validation.py", line 1147, in check_X_y
    X = check_array(
        ^^^^^^^^^^^^
  File "C:\Users\Akash\AppData\Local\Programs\Python\Python311\Lib\site-packages\sklearn\utils\validation.py", line 917, in check_array
    array = _asarray_with_order(array, order=order, dtype=dtype, xp=xp)
            ^^^^^^^^^^^^^^^^^^^^^^^^^^^^^^^^^^^^^^^^^^^^^^^^^^^^^^^^^^^
  File "C:\Users\Akash\AppData\Local\Programs\Python\Python311\Lib\site-packages\sklearn\utils\_array_api.py", line 380, in _asarray_with_order
    array = numpy.asarray(array, order=order, dtype=dtype)
            ^^^^^^^^^^^^^^^^^^^^^^^^^^^^^^^^^^^^^^^^^^^^^^
  File "C:\Users\Akash\AppData\Local\Programs\Python\Python311\Lib\site-packages\pandas\core\generic.py", line 1998, in __array__
    arr = np.asarray(values, dtype=dtype)
          ^^^^^^^^^^^^^^^^^^^^^^^^^^^^^^^
ValueError: could not convert string to float: ' Useful'

2023-09-14 13:04:02,955 - ERROR - 
All the 135 fits failed.
It is very likely that your model is misconfigured.
You can try to debug the error by setting error_score='raise'.

Below are more details about the failures:
--------------------------------------------------------------------------------
108 fits failed with the following error:
Traceback (most recent call last):
  File "C:\Users\Akash\AppData\Local\Programs\Python\Python311\Lib\site-packages\sklearn\model_selection\_validation.py", line 732, in _fit_and_score
    estimator.fit(X_train, y_train, **fit_params)
  File "C:\Users\Akash\AppData\Local\Programs\Python\Python311\Lib\site-packages\sklearn\base.py", line 1151, in wrapper
    return fit_method(estimator, *args, **kwargs)
           ^^^^^^^^^^^^^^^^^^^^^^^^^^^^^^^^^^^^^^
  File "C:\Users\Akash\AppData\Local\Programs\Python\Python311\Lib\site-packages\sklearn\ensemble\_forest.py", line 348, in fit
    X, y = self._validate_data(
           ^^^^^^^^^^^^^^^^^^^^
  File "C:\Users\Akash\AppData\Local\Programs\Python\Python311\Lib\site-packages\sklearn\base.py", line 621, in _validate_data
    X, y = check_X_y(X, y, **check_params)
           ^^^^^^^^^^^^^^^^^^^^^^^^^^^^^^^
  File "C:\Users\Akash\AppData\Local\Programs\Python\Python311\Lib\site-packages\sklearn\utils\validation.py", line 1147, in check_X_y
    X = check_array(
        ^^^^^^^^^^^^
  File "C:\Users\Akash\AppData\Local\Programs\Python\Python311\Lib\site-packages\sklearn\utils\validation.py", line 917, in check_array
    array = _asarray_with_order(array, order=order, dtype=dtype, xp=xp)
            ^^^^^^^^^^^^^^^^^^^^^^^^^^^^^^^^^^^^^^^^^^^^^^^^^^^^^^^^^^^
  File "C:\Users\Akash\AppData\Local\Programs\Python\Python311\Lib\site-packages\sklearn\utils\_array_api.py", line 380, in _asarray_with_order
    array = numpy.asarray(array, order=order, dtype=dtype)
            ^^^^^^^^^^^^^^^^^^^^^^^^^^^^^^^^^^^^^^^^^^^^^^
  File "C:\Users\Akash\AppData\Local\Programs\Python\Python311\Lib\site-packages\pandas\core\generic.py", line 1998, in __array__
    arr = np.asarray(values, dtype=dtype)
          ^^^^^^^^^^^^^^^^^^^^^^^^^^^^^^^
ValueError: could not convert string to float: ' Simulation'

--------------------------------------------------------------------------------
27 fits failed with the following error:
Traceback (most recent call last):
  File "C:\Users\Akash\AppData\Local\Programs\Python\Python311\Lib\site-packages\sklearn\model_selection\_validation.py", line 732, in _fit_and_score
    estimator.fit(X_train, y_train, **fit_params)
  File "C:\Users\Akash\AppData\Local\Programs\Python\Python311\Lib\site-packages\sklearn\base.py", line 1151, in wrapper
    return fit_method(estimator, *args, **kwargs)
           ^^^^^^^^^^^^^^^^^^^^^^^^^^^^^^^^^^^^^^
  File "C:\Users\Akash\AppData\Local\Programs\Python\Python311\Lib\site-packages\sklearn\ensemble\_forest.py", line 348, in fit
    X, y = self._validate_data(
           ^^^^^^^^^^^^^^^^^^^^
  File "C:\Users\Akash\AppData\Local\Programs\Python\Python311\Lib\site-packages\sklearn\base.py", line 621, in _validate_data
    X, y = check_X_y(X, y, **check_params)
           ^^^^^^^^^^^^^^^^^^^^^^^^^^^^^^^
  File "C:\Users\Akash\AppData\Local\Programs\Python\Python311\Lib\site-packages\sklearn\utils\validation.py", line 1147, in check_X_y
    X = check_array(
        ^^^^^^^^^^^^
  File "C:\Users\Akash\AppData\Local\Programs\Python\Python311\Lib\site-packages\sklearn\utils\validation.py", line 917, in check_array
    array = _asarray_with_order(array, order=order, dtype=dtype, xp=xp)
            ^^^^^^^^^^^^^^^^^^^^^^^^^^^^^^^^^^^^^^^^^^^^^^^^^^^^^^^^^^^
  File "C:\Users\Akash\AppData\Local\Programs\Python\Python311\Lib\site-packages\sklearn\utils\_array_api.py", line 380, in _asarray_with_order
    array = numpy.asarray(array, order=order, dtype=dtype)
            ^^^^^^^^^^^^^^^^^^^^^^^^^^^^^^^^^^^^^^^^^^^^^^
  File "C:\Users\Akash\AppData\Local\Programs\Python\Python311\Lib\site-packages\pandas\core\generic.py", line 1998, in __array__
    arr = np.asarray(values, dtype=dtype)
          ^^^^^^^^^^^^^^^^^^^^^^^^^^^^^^^
ValueError: could not convert string to float: ' Useful'

2023-09-14 14:11:48,667 - ERROR - This model's maximum context length is 4097 tokens, however you requested 4126 tokens (126 in your prompt; 4000 for the completion). Please reduce your prompt; or completion length.
2023-09-14 14:12:12,260 - ERROR - This model's maximum context length is 4097 tokens, however you requested 4126 tokens (126 in your prompt; 4000 for the completion). Please reduce your prompt; or completion length.
2023-09-14 14:48:34,744 - ERROR - name 'precision_score' is not defined
2023-09-14 14:48:55,590 - ERROR - name 'precision_score' is not defined
2023-09-14 15:01:22,224 - ERROR - 
All the 135 fits failed.
It is very likely that your model is misconfigured.
You can try to debug the error by setting error_score='raise'.

Below are more details about the failures:
--------------------------------------------------------------------------------
27 fits failed with the following error:
Traceback (most recent call last):
  File "C:\Users\Akash\AppData\Local\Programs\Python\Python311\Lib\site-packages\sklearn\model_selection\_validation.py", line 732, in _fit_and_score
    estimator.fit(X_train, y_train, **fit_params)
  File "C:\Users\Akash\AppData\Local\Programs\Python\Python311\Lib\site-packages\sklearn\base.py", line 1151, in wrapper
    return fit_method(estimator, *args, **kwargs)
           ^^^^^^^^^^^^^^^^^^^^^^^^^^^^^^^^^^^^^^
  File "C:\Users\Akash\AppData\Local\Programs\Python\Python311\Lib\site-packages\sklearn\ensemble\_forest.py", line 348, in fit
    X, y = self._validate_data(
           ^^^^^^^^^^^^^^^^^^^^
  File "C:\Users\Akash\AppData\Local\Programs\Python\Python311\Lib\site-packages\sklearn\base.py", line 621, in _validate_data
    X, y = check_X_y(X, y, **check_params)
           ^^^^^^^^^^^^^^^^^^^^^^^^^^^^^^^
  File "C:\Users\Akash\AppData\Local\Programs\Python\Python311\Lib\site-packages\sklearn\utils\validation.py", line 1147, in check_X_y
    X = check_array(
        ^^^^^^^^^^^^
  File "C:\Users\Akash\AppData\Local\Programs\Python\Python311\Lib\site-packages\sklearn\utils\validation.py", line 917, in check_array
    array = _asarray_with_order(array, order=order, dtype=dtype, xp=xp)
            ^^^^^^^^^^^^^^^^^^^^^^^^^^^^^^^^^^^^^^^^^^^^^^^^^^^^^^^^^^^
  File "C:\Users\Akash\AppData\Local\Programs\Python\Python311\Lib\site-packages\sklearn\utils\_array_api.py", line 380, in _asarray_with_order
    array = numpy.asarray(array, order=order, dtype=dtype)
            ^^^^^^^^^^^^^^^^^^^^^^^^^^^^^^^^^^^^^^^^^^^^^^
  File "C:\Users\Akash\AppData\Local\Programs\Python\Python311\Lib\site-packages\pandas\core\generic.py", line 1998, in __array__
    arr = np.asarray(values, dtype=dtype)
          ^^^^^^^^^^^^^^^^^^^^^^^^^^^^^^^
ValueError: could not convert string to float: 'Female'

--------------------------------------------------------------------------------
108 fits failed with the following error:
Traceback (most recent call last):
  File "C:\Users\Akash\AppData\Local\Programs\Python\Python311\Lib\site-packages\sklearn\model_selection\_validation.py", line 732, in _fit_and_score
    estimator.fit(X_train, y_train, **fit_params)
  File "C:\Users\Akash\AppData\Local\Programs\Python\Python311\Lib\site-packages\sklearn\base.py", line 1151, in wrapper
    return fit_method(estimator, *args, **kwargs)
           ^^^^^^^^^^^^^^^^^^^^^^^^^^^^^^^^^^^^^^
  File "C:\Users\Akash\AppData\Local\Programs\Python\Python311\Lib\site-packages\sklearn\ensemble\_forest.py", line 348, in fit
    X, y = self._validate_data(
           ^^^^^^^^^^^^^^^^^^^^
  File "C:\Users\Akash\AppData\Local\Programs\Python\Python311\Lib\site-packages\sklearn\base.py", line 621, in _validate_data
    X, y = check_X_y(X, y, **check_params)
           ^^^^^^^^^^^^^^^^^^^^^^^^^^^^^^^
  File "C:\Users\Akash\AppData\Local\Programs\Python\Python311\Lib\site-packages\sklearn\utils\validation.py", line 1147, in check_X_y
    X = check_array(
        ^^^^^^^^^^^^
  File "C:\Users\Akash\AppData\Local\Programs\Python\Python311\Lib\site-packages\sklearn\utils\validation.py", line 917, in check_array
    array = _asarray_with_order(array, order=order, dtype=dtype, xp=xp)
            ^^^^^^^^^^^^^^^^^^^^^^^^^^^^^^^^^^^^^^^^^^^^^^^^^^^^^^^^^^^
  File "C:\Users\Akash\AppData\Local\Programs\Python\Python311\Lib\site-packages\sklearn\utils\_array_api.py", line 380, in _asarray_with_order
    array = numpy.asarray(array, order=order, dtype=dtype)
            ^^^^^^^^^^^^^^^^^^^^^^^^^^^^^^^^^^^^^^^^^^^^^^
  File "C:\Users\Akash\AppData\Local\Programs\Python\Python311\Lib\site-packages\pandas\core\generic.py", line 1998, in __array__
    arr = np.asarray(values, dtype=dtype)
          ^^^^^^^^^^^^^^^^^^^^^^^^^^^^^^^
ValueError: could not convert string to float: 'Male'

2023-09-14 15:06:06,366 - ERROR - name 'precision_score' is not defined
2023-09-14 15:16:55,679 - ERROR - pos_label=Y is not a valid label. It should be one of [0, 1]
2023-09-14 15:24:36,401 - ERROR - [Errno 2] No such file or directory: 'api/uploads/Loan_data.csv'
2023-09-14 15:27:18,952 - ERROR - [WinError 32] The process cannot access the file because it is being used by another process: 'api/uploads/generated_data.csv'
2023-09-14 15:27:18,958 - ERROR - [Errno 2] No such file or directory: 'api/uploads/Loan_data.csv'
2023-09-14 15:27:18,965 - ERROR - [Errno 2] No such file or directory: 'api/uploads/Loan_data.csv'
2023-09-14 15:27:18,971 - ERROR - [Errno 2] No such file or directory: 'api/uploads/Loan_data.csv'
2023-09-14 15:27:18,977 - ERROR - [Errno 2] No such file or directory: 'api/uploads/Loan_data.csv'
2023-09-14 15:27:18,983 - ERROR - [Errno 2] No such file or directory: 'api/uploads/Loan_data.csv'
2023-09-14 15:27:18,987 - ERROR - [Errno 2] No such file or directory: 'api/uploads/Loan_data.csv'
2023-09-14 15:27:18,990 - ERROR - [Errno 2] No such file or directory: 'api/uploads/Loan_data.csv'
2023-09-14 15:27:18,994 - ERROR - [Errno 2] No such file or directory: 'api/uploads/Loan_data.csv'
2023-09-14 15:27:19,000 - ERROR - [Errno 2] No such file or directory: 'api/uploads/Loan_data.csv'
2023-09-14 15:36:40,563 - ERROR - unsupported operand type(s) for +: 'int' and 'str'
2023-09-14 15:37:00,392 - ERROR - unsupported operand type(s) for +: 'int' and 'str'
2023-09-14 15:42:13,892 - ERROR - [Errno 2] No such file or directory: 'api/uploads/Loan_data_Predict.csv'
2023-09-14 15:46:27,444 - ERROR - Error tokenizing data. C error: Expected 13 fields in line 43, saw 18

2023-09-14 15:46:27,758 - ERROR - Error tokenizing data. C error: Expected 13 fields in line 43, saw 18

2023-09-14 15:48:21,735 - ERROR - Error tokenizing data. C error: Expected 13 fields in line 43, saw 18

2023-09-14 15:48:21,738 - ERROR - Error tokenizing data. C error: Expected 13 fields in line 43, saw 18

2023-09-14 15:50:43,738 - ERROR - Error tokenizing data. C error: Expected 13 fields in line 43, saw 18

2023-09-14 15:50:43,742 - ERROR - Error tokenizing data. C error: Expected 13 fields in line 43, saw 18

2023-09-14 15:51:38,767 - ERROR - Error tokenizing data. C error: Expected 13 fields in line 43, saw 18

2023-09-14 15:51:52,641 - ERROR - Error tokenizing data. C error: Expected 13 fields in line 43, saw 18

2023-09-14 15:51:53,463 - ERROR - Error tokenizing data. C error: Expected 13 fields in line 43, saw 18

2023-09-14 15:52:03,202 - ERROR - Error tokenizing data. C error: Expected 13 fields in line 43, saw 18

2023-09-14 16:11:10,047 - ERROR - Incorrect API key provided: sk-A3ieb***************************************deYp. You can find your API key at https://platform.openai.com/account/api-keys.
2023-09-14 16:12:08,117 - ERROR - Incorrect API key provided: sk-A3ieb***************************************deYp. You can find your API key at https://platform.openai.com/account/api-keys.
2023-09-14 16:14:13,154 - ERROR - Incorrect API key provided: sk-A3ieb***************************************deYp. You can find your API key at https://platform.openai.com/account/api-keys.
2023-09-14 16:16:13,823 - ERROR - Incorrect API key provided: sk-A3ieb***************************************deYp. You can find your API key at https://platform.openai.com/account/api-keys.
2023-09-14 16:17:43,959 - ERROR - Incorrect API key provided: sk-A3ieb***************************************deYp. You can find your API key at https://platform.openai.com/account/api-keys.
2023-09-14 16:19:22,930 - ERROR - Incorrect API key provided: sk-A3ieb***************************************deYp. You can find your API key at https://platform.openai.com/account/api-keys.
2023-09-14 16:19:46,568 - ERROR - Incorrect API key provided: sk-A3ieb***************************************deYp. You can find your API key at https://platform.openai.com/account/api-keys.
2023-09-14 16:20:03,178 - ERROR - Incorrect API key provided: sk-A3ieb***************************************deYp. You can find your API key at https://platform.openai.com/account/api-keys.
2023-09-14 16:20:04,880 - ERROR - Incorrect API key provided: sk-A3ieb***************************************deYp. You can find your API key at https://platform.openai.com/account/api-keys.
2023-09-14 16:20:09,014 - ERROR - Incorrect API key provided: sk-A3ieb***************************************deYp. You can find your API key at https://platform.openai.com/account/api-keys.
2023-09-14 17:33:48,972 - ERROR - You exceeded your current quota, please check your plan and billing details.
2023-09-14 17:34:45,428 - ERROR - You exceeded your current quota, please check your plan and billing details.
